# Translations template for paxes_cinder.
# Copyright (C) 2014 NCO Corp.
# This file is distributed under the same license as the paxes_cinder
# project.
# FIRST AUTHOR <EMAIL@ADDRESS>, 2014.
#
#, fuzzy
msgid ""
msgstr ""
"Project-Id-Version: paxes_cinder 1.2.1.0\n"
"Report-Msgid-Bugs-To: nguyen1d@us.ibm.com\n"
"POT-Creation-Date: 2014-04-24 16:04-0400\n"
"PO-Revision-Date: YEAR-MO-DA HO:MI+ZONE\n"
"Last-Translator: FULL NAME <EMAIL@ADDRESS>\n"
"Language-Team: LANGUAGE <LL@li.org>\n"
"MIME-Version: 1.0\n"
"Content-Type: text/plain; charset=utf-8\n"
"Content-Transfer-Encoding: 8bit\n"
"Generated-By: Babel 1.3\n"

#: paxes_cinder/k2aclient/openstack/common/gettextutils.py:255
msgid "Message objects do not support addition."
msgstr "NV-C33F89C メッセージ・オブジェクトは追加機能をサポートしていません。"

#: paxes_cinder/k2aclient/openstack/common/gettextutils.py:264
msgid ""
"Message objects do not support str() because they may contain non-ascii "
"characters. Please use unicode() or translate() instead."
msgstr ""
"NV-64408AE メッセージ・オブジェクトは非 ASCII 文字を含む可能性があるため str() をサポートしません。代わりに "
"unicode() または translate() を使用してください。"

#: paxes_cinder/k2aclient/openstack/common/procutils.py:129
#, python-format
msgid "Got unknown keyword args to utils.execute: %r"
msgstr "NV-36AD129 utils.execute の不明なキーワード引数を受け取りました: %r"

#: paxes_cinder/k2aclient/openstack/common/procutils.py:144
#, python-format
msgid "Running cmd (subprocess): %s"
msgstr "NV-9F83237 コマンド (サブプロセス) の実行中: %s"

#: paxes_cinder/k2aclient/openstack/common/procutils.py:169
#: paxes_cinder/k2aclient/openstack/common/procutils.py:241
#, python-format
msgid "Result was %s"
msgstr "NV-E91D667 結果は %s でした"

#: paxes_cinder/k2aclient/openstack/common/procutils.py:181
#, python-format
msgid "%r failed. Retrying."
msgstr "NV-E62FA94 %r が失敗しました。再試行しています。"

#: paxes_cinder/k2aclient/openstack/common/procutils.py:220
#, python-format
msgid "Running cmd (SSH): %s"
msgstr "NV-F226973 コマンド (SSH) の実行中: %s"

#: paxes_cinder/k2aclient/openstack/common/procutils.py:222
msgid "Environment not supported over SSH"
msgstr "NV-5D0CD8B 環境は SSH でサポートされていません"

#: paxes_cinder/k2aclient/openstack/common/procutils.py:226
msgid "process_input not supported over SSH"
msgstr "NV-E78B011 SSH で process_input は サポートされていません"

#: paxes_cinder/volume/drivers/svc/storwize_svc_driver_id.py:512
#, python-format
msgid "DB error: %s"
msgstr "NV-B907287 DB エラー: %s"

#: paxes_cinder/k2aclient/shell.py:100
msgid "Print debugging output"
msgstr "デバッグ出力の印刷"

#: paxes_cinder/api/plugins/__init__.py:31
#, python-format
msgid "Failed to load extension %(name)s: %(ex)s"
msgstr "NV-E1E174C 拡張 %(name)s のロードに失敗しました: %(ex)s"

#: paxes_cinder/volume/manager.py:1275
#, python-format
msgid "Driver %s does not implement Discover Driver"
msgstr "NV-DA200A2 ドライバー %s は「ドライバーのディスカバー」を実装しません"

#: paxes_cinder/exception.py:16
#, python-format
msgid "Connection control failure: %(reason)s"
msgstr "NV-BFC4353 接続制御障害: %(reason)s"

#: paxes_cinder/exception.py:20
#, python-format
msgid "Zone operation failed: %(reason)s"
msgstr "NV-A619680 ゾーン操作が失敗しました: %(reason)s"

#: paxes_cinder/exception.py:24
#, python-format
msgid "FC SAN Lookup failure: %(reason)s"
msgstr "NV-1316051 FC SAN ルックアップ障害: %(reason)s"

#: paxes_cinder/exception.py:32
#, python-format
msgid "Internal Misconfiguration detected: %(reason)s"
msgstr "NV-C9F5A2A 内部の構成の誤りが検出されました: %(reason)s"

#: paxes_cinder/exception.py:58
#, python-format
msgid "Fabric '%(display_name)s' (%(username)s@%(ip)s:%(port)s)"
msgstr "NV-097D384 ファブリック '%(display_name)s' (%(username)s@%(ip)s:%(port)s)"

#: paxes_cinder/exception.py:93
#, python-format
msgid "%(descriptor)s: %(message)s"
msgstr "NV-12DC37C %(descriptor)s: %(message)s"

#: paxes_cinder/exception.py:142
#, python-format
msgid "%(problem)s: %(err)s"
msgstr "NV-7FA8022 %(problem)s: %(err)s"

#: paxes_cinder/exception.py:164
msgid "Could not authenticate with the specified credentials"
msgstr "NV-BB4FAEC 指定された資格情報で認証できませんでした"

#: paxes_cinder/exception.py:174
#, python-format
msgid "Timeout (%(timeout)s seconds) when attempting to connect"
msgstr "NV-3AB9750 接続しようとしているときにタイムアウトになりました (%(timeout)s 秒)"

#: paxes_cinder/exception.py:184
#, python-format
msgid "Timeout (%(timeout)s seconds) when executing command %(cmd)s"
msgstr "NV-17277CD コマンド %(cmd)s の実行中にタイムアウトになりました (%(timeout)s 秒)"

#: paxes_cinder/exception.py:193
#, python-format
msgid "Could not connect: %(error)s %(detail)s"
msgstr "NV-2251927 接続できませんでした: %(error)s %(detail)s"

#: paxes_cinder/exception.py:201
#, python-format
msgid ""
"Another transaction was already in progress when attempting to execute "
"command '%(cmd)s'"
msgstr "NV-B3EE2A1 コマンド '%(cmd)s' を実行しようとしたときに、既に別のトランザクションが進行中でした"

#: paxes_cinder/exception.py:209
#, python-format
msgid ""
"Zone DB exceeded size limits when executing command '%(cmd)s', which "
"returned '%(res)s'"
msgstr "NV-3D73335 コマンド '%(cmd)s' の実行中にゾーン DB がサイズ制限を超えたため、'%(res)s' が返されました"

#: paxes_cinder/exception.py:218
#, python-format
msgid "The CLI command '%(cmd)s' returned an unexpected response '%(res)s'"
msgstr "NV-6BC3B8F CLI コマンド '%(cmd)s' が、予期しない応答 '%(res)s' を返しました"

#: paxes_cinder/exception.py:240
#, python-format
msgid "Storage %(display_name)s (%(username)s@%(ip)s:%(port)s)"
msgstr "NV-FD8FAF8 ストレージ %(display_name)s (%(username)s@%(ip)s:%(port)s)"

#: paxes_cinder/exception.py:272
msgid "No more host definitions can be created"
msgstr "NV-FAE0982 ホスト定義はこれ以上作成できません"

#: paxes_cinder/exception.py:281
msgid "No more flashcopy mappings can be created"
msgstr "NV-5071C44 FlashCopy マッピングはこれ以上作成できません"

#: paxes_cinder/exception.py:289
msgid "Could not connect, possibly due to too many connections."
msgstr "NV-16C6099 接続できませんでした。原因として、接続数が多すぎる可能性があります。"

#: paxes_cinder/exception.py:297
#, python-format
msgid ""
"Could not map vdisk %(vdisk_id)s to host %(host)s because it is already "
"mapped to another host"
msgstr ""
"NV-4B128AE 仮想ディスク %(vdisk_id)s は、既に別のホストにマップされているため、ホスト %(host)s "
"にマップできませんでした"

#: paxes_cinder/exception.py:312
#, python-format
msgid "vdisk %(vdisk_id)s does not exist"
msgstr "NV-8AE54C7 仮想ディスク %(vdisk_id)s が存在しません"

#: paxes_cinder/exception.py:322
msgid "No common fabrics between virtual machine and storage"
msgstr "NV-E5685D0 仮想マシンとストレージの間に共通ファブリックがありません"

#: paxes_cinder/exception.py:339
#, python-format
msgid ""
"vdisk %(vdisk_id)s has been deleted and recreated. Expected UID is "
"%(expected_uid)s, current UID is %(current_uid)s"
msgstr ""
"NV-78057E1 仮想ディスク %(vdisk_id)s は削除されて再作成されました。予期された UID は "
"%(expected_uid)s で、現在の UID は %(current_uid)s です"

#: paxes_cinder/exception.py:350
#, python-format
msgid ""
"Not enough space left on storage host %(host)s to extend the volume "
"%(volume_id)s"
msgstr "NV-EA431AC ストレージ・ホスト %(host)s には、ボリューム %(volume_id)s を拡張するための十分なスペースがありません"

#: paxes_cinder/exception.py:360
msgid ""
"Flashcopy is in progress for boot volume, volume size didn't change. "
"Please try again later."
msgstr "NV-461A839 ブート・ボリュームの FlashCopy が進行中です。ボリューム・サイズは変更されませんでした。後で再試行してください。"

#: paxes_cinder/exception.py:367
#, python-format
msgid ""
"vdisk %(vdisk_id)s is source of snapshot flashcopy and fcmap %(fcmapid)s "
"cannot be removed."
msgstr ""
"NV-CB3AB35 仮想ディスク %(vdisk_id)s はスナップショット FlashCopy のソースであり、fcmap "
"%(fcmapid)s を削除することはできません。"

#: paxes_cinder/db/sqlalchemy/migrate_repo/versions/001_ibm_paxes_v1r2.py:35
#, python-format
msgid "Exception creating table %(table)s: %(ex_str)s"
msgstr "テーブル %(table)s を作成するときに例外が発生しました: %(ex_str)s"

#: paxes_cinder/db/sqlalchemy/migrate_repo/versions/001_ibm_paxes_v1r2.py:55
#, python-format
msgid "Exception dropping table %(table)s: %(ex_str)s"
msgstr "テーブル %(table)s を除去するときに例外が発生しました: %(ex_str)s"

#: paxes_cinder/fabric/map_initiators.py:70
msgid ""
"Could not obtain a fabric manager client. Fibre Channel switch fabrics "
"may not be registered."
msgstr ""
"NV-6EF68AC "
"ファブリック・マネージャー・クライアントを取得できませんでした。ファイバー・チャネル・スイッチ・ファブリックは登録されていない可能性があります。"

#: paxes_cinder/fabric/map_initiators.py:85
#, python-format
msgid ""
"Unable to retrieve WWPN initiator information from one or more fabric "
"switches. Error: %(ex_str)s"
msgstr "1 つ以上のファブリック・スイッチから WWPN イニシエーター情報を取得できません。エラー: %(ex_str)s"

#: paxes_cinder/fabric/map_initiators.py:119
msgid "No fabrics registered."
msgstr "NV-0AA1511 ファブリックは登録されていません。"

#: paxes_cinder/fabric/map_initiators.py:124
msgid "No fabric names registered."
msgstr "NV-A4978F0 ファブリック名は登録されていません。"

#: paxes_cinder/k2aclient/client.py:104
msgid ", during get"
msgstr "NV-C758794 、取得中"

#: paxes_cinder/k2aclient/client.py:127
msgid ", during refresh"
msgstr "NV-A09A06D 、リフレッシュ中"

#: paxes_cinder/k2aclient/client.py:148
#: paxes_cinder/k2aclient/client.py:172
msgid ", during create"
msgstr "NV-16332E7 、作成中"

#: paxes_cinder/k2aclient/client.py:193
msgid ", during delete"
msgstr "NV-B5BE602 、削除中"

#: paxes_cinder/k2aclient/client.py:207
msgid ", during runJob"
msgstr "NV-9A12874 、runJob 中"

#: paxes_cinder/k2aclient/client.py:219
msgid ", during readJob"
msgstr "NV-EA9B845 、readJob 中"

#: paxes_cinder/k2aclient/client.py:234
msgid ", during authenticate"
msgstr "NV-DD96084 、認証中"

#: paxes_cinder/k2aclient/client.py:247
#, python-format
msgid ""
"k2aclient: while obtaining client, invalid client version >%(version)s<. "
"must be one of: >%(versions)s<"
msgstr ""
"k2aclient: クライアントの取得中に無効なクライアント・バージョン >%(version)s< "
"が見つかりました。次のいずれかでなければなりません: >%(versions)s<"

#: paxes_cinder/k2aclient/exceptions.py:46
#: paxes_cinder/k2aclient/exceptions.py:307
#, python-format
msgid ", exception diagnostics have been written to: >%s<"
msgstr "、例外の診断が >%s< に書き込まれました"

#: paxes_cinder/k2aclient/exceptions.py:56
#, python-format
msgid "Other Exception off of K2: >%s<"
msgstr "NV-92A2EB5 K2 からのその他の例外: >%s<"

#: paxes_cinder/k2aclient/exceptions.py:58
#: paxes_cinder/k2aclient/exceptions.py:78
#: paxes_cinder/k2aclient/exceptions.py:88
#: paxes_cinder/k2aclient/exceptions.py:105
#, python-format
msgid ", during: >%s<"
msgstr "、>%s< 中"

#: paxes_cinder/k2aclient/exceptions.py:66
#, python-format
msgid "SSL exception off of K2: >%s<"
msgstr "NV-852F651 K2 からの SSL 例外: >%s<"

#: paxes_cinder/k2aclient/exceptions.py:76
#, python-format
msgid "Connection exception off of K2: >%s<"
msgstr "NV-DE65980 K2 からの接続例外: >%s<"

#: paxes_cinder/k2aclient/exceptions.py:86
#, python-format
msgid "Timeout exception off of K2: >%s<"
msgstr "NV-DC27602 K2 からのタイムアウト例外: >%s<"

#: paxes_cinder/k2aclient/exceptions.py:100
#, python-format
msgid "K2Error off of K2: >%(msg)s<, Status: >%(status)d<, k2Error: >%(k2error)s<"
msgstr "K2 からの K2Error: >%(msg)s<、状況: >%(status)d<、k2Error: >%(k2error)s<"

#: paxes_cinder/k2aclient/exceptions.py:122
msgid "Bad Request"
msgstr "正しくない要求"

#: paxes_cinder/k2aclient/exceptions.py:130
msgid "Unauthorized"
msgstr "許可されません"

#: paxes_cinder/k2aclient/exceptions.py:144
msgid "Forbidden"
msgstr "禁止"

#: paxes_cinder/k2aclient/exceptions.py:158
msgid "Not Found"
msgstr "見つかりません"

#: paxes_cinder/k2aclient/exceptions.py:167
msgid "Method Not Allowed"
msgstr "許可されない方式"

#: paxes_cinder/k2aclient/exceptions.py:177
msgid "Not Acceptable"
msgstr "受け入れ不可"

#: paxes_cinder/k2aclient/exceptions.py:189
msgid "Conflict"
msgstr "矛盾"

#: paxes_cinder/k2aclient/exceptions.py:197
msgid "PreCondition failed"
msgstr "前提条件が満たされていませんでした"

#: paxes_cinder/k2aclient/exceptions.py:206
msgid "Request Body Too Large"
msgstr "要求本体が大きすぎます"

#: paxes_cinder/k2aclient/exceptions.py:216
msgid "Unsupported Media Type"
msgstr "サポートされないメディア・タイプ"

#: paxes_cinder/k2aclient/exceptions.py:225
msgid "Internal Server Error"
msgstr "内部サーバー・エラー"

#: paxes_cinder/k2aclient/exceptions.py:235
msgid "Not Implemented"
msgstr "実装されていません"

#: paxes_cinder/k2aclient/exceptions.py:245
msgid "Service Unavailable"
msgstr "サービス使用不可"

#: paxes_cinder/k2aclient/exceptions.py:255
msgid "HTTP Version Not Supported"
msgstr "サポートされない HTTP バージョン"

#: paxes_cinder/k2aclient/exceptions.py:263
msgid "Not Classified"
msgstr "未分類"

#: paxes_cinder/k2aclient/k2exclogger.py:114
#, python-format
msgid ""
"k2aclient: during FFDC, cant create k2 exception log directory: >%s<, "
"will disable k2 exception logging .."
msgstr ""
"NV-ED6E0F0 k2aclient: FFDC 中、k2 例外ログ・ディレクトリー >%s< を作成できません。k2 "
"例外ロギングを使用不可にします.."

#: paxes_cinder/k2aclient/k2exclogger.py:123
#, python-format
msgid ""
"k2aclient: during FFDC, cant write to k2 exception log directory: >%s<, "
"will disable k2 exception logging .."
msgstr ""
"NV-6373107 k2aclient: FFDC 中、k2 例外ログ・ディレクトリー >%s< に書き込めません。k2 "
"例外ロギングを使用不可にします.."

#: paxes_cinder/k2aclient/k2exclogger.py:146
#, python-format
msgid ""
"k2aclient: during FFDC,  caught an exception while writing to log "
"directory: >%s<, will disable k2 exception logging .."
msgstr ""
"NV-3376E54 k2aclient: FFDC 中、ログ・ディレクトリー >%s< に書き込んでいるときに例外を受け取りました。k2 "
"例外ロギングを使用不可にします.."

#: paxes_cinder/k2aclient/shell.py:59
#, python-format
msgid ""
"k2aclient: error: %(errmsg)s\n"
"Try '%(mainp)s help %(subp)s' for more information.\n"
msgstr ""
"k2aclient: エラー: %(errmsg)s\n"
"詳しくは、'%(mainp)s help %(subp)s' を試行してください。\n"

#: paxes_cinder/k2aclient/shell.py:80
msgid "See \"k2a help COMMAND\" for help on a specific command."
msgstr "特定のコマンドのヘルプについては、『k2a help コマンド』を参照してください。"

#: paxes_cinder/k2aclient/shell.py:106
msgid "Accepts 1,defaults to env[K2A_API_VERSION]."
msgstr "1 を受け入れます。デフォルトは env[K2A_API_VERSION] です。"

#: paxes_cinder/k2aclient/shell.py:109
msgid "Number of retries when attempting k2 operations."
msgstr "k2 操作を試行するときの再試行回数。"

#: paxes_cinder/k2aclient/shell.py:119
msgid "url for k2 hmc, defaults to env[K2_URL]."
msgstr "k2 hmc の URL。デフォルトは env[K2_URL] です。"

#: paxes_cinder/k2aclient/shell.py:125
msgid "k2 username, defaults to env[K2_USERNAME]."
msgstr "k2 ユーザー名。デフォルトは env[K2_USERNAME] です。"

#: paxes_cinder/k2aclient/shell.py:131
msgid "k2 password, defaults to env[K2_PASSWORD]."
msgstr "k2 パスワード。デフォルトは env[K2_PASSWORD] です。"

#: paxes_cinder/k2aclient/shell.py:138
msgid ""
"k2 auditmemento, defaults to, if set, env[K2_AUDITMEMENTO], otherwise to "
"\"k2a\"."
msgstr "k2 auditmemento。デフォルトは、設定する場合は env[K2_AUDITMEMENTO] で、設定しない場合は \"k2a\" です。"

#: paxes_cinder/k2aclient/shell.py:145
msgid "k2 certpath, defaults to, if set, env[K2_CERTPATH], otherwise to None."
msgstr "k2 certpath。デフォルトは、設定する場合は env[K2_CERTPATH] で、設定しない場合は「なし」です。"

#: paxes_cinder/k2aclient/shell.py:152
msgid ""
"log directory, defaults to, if set, env[K2A_LOGDIR], otherwise to None. "
"None turnsoff file logging"
msgstr ""
"ログ・ディレクトリー。デフォルトは、設定する場合は env[K2A_LOGDIR] "
"で、設定しない場合は「なし」です。「なし」にすると、ファイル・ロギングはオフになります"

#: paxes_cinder/k2aclient/shell.py:171
msgid ""
"directory where k2aexc subdirectorywill be placedie \"<excdir>/k2aexc\", "
"defaults to, if set, env[K2A_EXCDIR], otherwise to /tmp"
msgstr ""
"k2aexc サブディレクトリーを配置するディレクトリー \"<excdir>/k2aexc\"。デフォルトは、設定する場合は "
"env[K2A_EXCDIR] で、設定しない場合は /tmp です"

#: paxes_cinder/k2aclient/shell.py:309
msgid ""
"k2aclient: you must provide a url for a k2 hmc via either --k2-url or "
"env[K2_URL]"
msgstr ""
"NV-D20F7FC k2aclient: --k2-url または env[K2_URL] のいずれかを使用して、k2 hmc の URL "
"を指定する必要があります"

#: paxes_cinder/k2aclient/shell.py:315
msgid ""
"k2aclient: you must provide a k2 username via either --k2-username or "
"env[K2_USERNAME]"
msgstr ""
"NV-996BCEC k2aclient: --k2-username または env[K2_USERNAME] のいずれかを使用して、k2 "
"ユーザー名を指定する必要があります"

#: paxes_cinder/k2aclient/shell.py:321
msgid ""
"k2aclient: you must provide a k2 password via either --k2-password or via"
" env[K2_PASSWORD]"
msgstr ""
"NV-EB948AA k2aclient: --k2-password または env[K2_PASSWORD] のいずれかを使用して、k2 "
"パスワードを指定する必要があります"

#: paxes_cinder/k2aclient/shell.py:355
#, python-format
msgid "Display help for %s"
msgstr "%s のヘルプを表示します"

#: paxes_cinder/k2aclient/shell.py:364
#, python-format
msgid "k2aclient:>%s< is not a valid subcommand"
msgstr "NV-DAC982A k2aclient:>%s< は無効なサブコマンドです"

#: paxes_cinder/k2aclient/shell.py:384
msgid "... terminating k2a client"
msgstr "NV-56344DF ... k2a クライアントの終了中"

#: paxes_cinder/k2aclient/shell.py:389
#, python-format
msgid "ERROR: type: >%(type)s<, msg: >%(e)s<"
msgstr "NV-9BF8F90 エラー: タイプ: >%(type)s<、メッセージ: >%(e)s<"

#: paxes_cinder/k2aclient/utils.py:101
#, python-format
msgid "k2aclient: no %(res)s with a name or ID of '%(name_or_id)s' exists."
msgstr "NV-63A28A2 k2aclient: %(res)s のうち、名前または ID が '%(name_or_id)s' のものは存在しません。"

#: paxes_cinder/k2aclient/utils.py:108
#, python-format
msgid ""
"k2aclient: multiple %(res)s matches found for '%(name_or_id)s', use an ID"
" to be more specific."
msgstr ""
"NV-9ACDF38 k2aclient: 複数の %(res)s の一致が '%(name_or_id)s' "
"に対して見つかりました。より具体的な結果を得るには ID を使用してください。"

#: paxes_cinder/k2aclient/k2asample/k2_ssp_cluster_vios_snap.py:144
#: paxes_cinder/k2aclient/v1/virtualioserver_manager.py:138
#, python-format
msgid "during directory preparation, cant create directory:  >%s<"
msgstr "NV-64A449C ディレクトリー準備の間に、次のディレクトリーを作成できません: >%s<"

#: paxes_cinder/k2aclient/k2asample/k2_ssp_cluster_vios_snap.py:150
#: paxes_cinder/k2aclient/v1/virtualioserver_manager.py:144
#, python-format
msgid "during directory preparation, cant write to directory:  >%s<"
msgstr "NV-C96CB61 ディレクトリー準備の間に、次のディレクトリーに書き込むことができません: >%s<"

#: paxes_cinder/k2aclient/k2asample/k2_ssp_cluster_vios_snap.py:181
#: paxes_cinder/k2aclient/k2asample/k2_ssp_etag_test.py:44
#: paxes_cinder/k2aclient/k2asample/tool_ssp_simulation.py:228
#, python-format
msgid "Node: >%s<, has no virtual_io_server, continuing ..."
msgstr "NV-60D657D ノード >%s< に virtual_io_server がありません。続行します..."

#: paxes_cinder/k2aclient/k2asample/k2_ssp_cluster_vios_snap.py:192
#: paxes_cinder/k2aclient/k2asample/k2_ssp_etag_test.py:55
#: paxes_cinder/k2aclient/k2asample/tool_ssp_simulation.py:239
#, python-format
msgid "Failed to retrieve node: >%s<, msg: >%s<, continuing ..."
msgstr "NV-0B99A4D ノード >%s< を取得できませんでした。メッセージ: >%s<。続行します..."

#: paxes_cinder/k2aclient/openstack/common/lockutils.py:276
#, python-format
msgid "Released file lock \"%(lock)s\" at %(path)s for method \"%(method)s\"..."
msgstr ""
"NV-F6B31F1 メソッド \"%(method)s\" のファイル・ロック \"%(lock)s\" を %(path)s "
"で解放しました..."

#: paxes_cinder/k2aclient/v1/cluster_manager.py:98
#, python-format
msgid ""
"k2aclient: during lu_linked_clone_of_lu, source_lu_udid: "
">%(source_lu_udid)s<, not in sharedstoragepool: >%(ssp.id)s<"
msgstr ""
"NV-69F0ACE k2aclient: lu_linked_clone_of_lu 中、source_lu_udid "
">%(source_lu_udid)s< が sharedstoragepool >%(ssp.id)s< にありません"

#: paxes_cinder/k2aclient/v1/cluster_manager.py:221
#, python-format
msgid ""
"k2aclient: for cluster id : >%(cluster.id)s<,  during lu_linked_clone, "
"for SourceUDID: >%(sourceUDID)s<, and DestinationUDID: "
">%(destinationUDID)s<, experienced job failure, job_id: "
">%(jresponse.job_id)s<, status: >%(jresponse.status)s<, input K2 job "
"diagnostics have been written to: >%(diagfspeci)s<, response k2 job "
"diagnostics have been written to: >%(diagfspec)s<"
msgstr ""
"k2aclient: クラスター ID >%(cluster.id)s< において、lu_linked_clone の間に、SourceUDID "
">%(sourceUDID)s< と DestinationUDID >%(destinationUDID)s< "
"でジョブ障害が発生しました。job_id: >%(jresponse.job_id)s<、状況: "
">%(jresponse.status)s<。入力 K2 ジョブ診断が >%(diagfspeci)s< に書き込まれました。応答 k2 "
"ジョブ診断が >%(diagfspec)s< に書き込まれました。"

#: paxes_cinder/k2aclient/v1/cluster_manager.py:335
#, python-format
msgid ""
"k2aclient: for cluster id : >%(cluster.id)s<,  during lu_create, for "
"lu_unit_name: >%(lu_unit_name)s<, with lu_unit_capacity: "
">%(lu_unit_capacity)s<, experienced job failure, job_id: "
">%(jresponse.job_id)s<, status: >%(jresponse.status)s<, input K2 job "
"diagnostics have been written to: >%(diagfspeci)s<, response k2 job "
"diagnostics have been written to: >%(diagfspec)s<"
msgstr ""
"k2aclient: クラスター ID >%(cluster.id)s< において、lu_create の間に、lu_unit_capacity "
">%(lu_unit_capacity)s< の lu_unit_name >%(lu_unit_name)s< "
"でジョブ障害が発生しました。job_id: >%(jresponse.job_id)s<、状況: "
">%(jresponse.status)s<。入力 K2 ジョブ診断が >%(diagfspeci)s< に書き込まれました。応答 k2 "
"ジョブ診断が >%(diagfspec)s< に書き込まれました。"

#: paxes_cinder/k2aclient/v1/logicalpartition_manager.py:126
#: paxes_cinder/k2aclient/v1/logicalpartition_manager.py:191
#, python-format
msgid ""
"k2aclient: during power_on, for LogicalPartition: "
">%(logicalpartition.id)s<, failed to power on due to job failure, job_id:"
" >%(jresponse.job_id)s<, status: >%(jresponse.status)s<, input K2 job "
"diagnostics have been written to: >%(diagfspeci)s<, response k2 job "
"diagnostics have been written to: >%(diagfspec)s<"
msgstr ""
"k2aclient: power_on の間に、LogicalPartition >%(logicalpartition.id)s< "
"で、ジョブ障害が原因でパワーオンが失敗しました。job_id: >%(jresponse.job_id)s<、状況: "
">%(jresponse.status)s<。入力 K2 ジョブ診断が >%(diagfspeci)s< に書き込まれました。応答 k2 "
"ジョブ診断が >%(diagfspec)s< に書き込まれました。"

#: paxes_cinder/k2aclient/v1/managementconsole_manager.py:77
#, python-format
msgid ""
"CLIRunner: ManagementConsole: >%(mc.id)s<, failed to run cmd: >%(cmd)s< "
"due to job failure, job_id: >%(jresponse.job_id)s<, status: "
">%(jresponse.status)s<, input K2 job diagnostics have been written to: "
">%(diagfspeci)s<,  response k2 job diagnostics have been written to: "
">%(diagfspec)s<"
msgstr ""
"CLIRunner: ジョブ障害が原因で、ManagementConsole >%(mc.id)s< がコマンド >%(cmd)s< "
"を実行できませんでした。job_id: >%(jresponse.job_id)s<、状況: >%(jresponse.status)s<。入力 "
"K2 ジョブ診断が >%(diagfspeci)s< に書き込まれました。応答 k2 ジョブ診断が >%(diagfspec)s< "
"に書き込まれました。"

#: paxes_cinder/k2aclient/v1/paxes_manager.py:108
#, python-format
msgid ""
"SharedStoragePool: While attempting to access Cluster: >%s<, unable to "
"connect to HMC: >%s<"
msgstr "SharedStoragePool: クラスター >%s< へのアクセス試行中に、HMC >%s< に接続できません"

#: paxes_cinder/k2aclient/v1/paxes_manager.py:110
msgid "Check the HMC and its configuration."
msgstr "HMC とその構成を確認してください。"

#: paxes_cinder/k2aclient/v1/paxes_manager.py:111
#, python-format
msgid "SharedStoragePool: Able to connect to HMC: >%s< for Cluster: >%s<"
msgstr "SharedStoragePool: HMC >%s< に接続できます (クラスター: >%s<)"

#: paxes_cinder/k2aclient/v1/paxes_manager.py:113
#, python-format
msgid "SharedStoragePool: Couldn't access Cluster: >%s<"
msgstr "SharedStoragePool: クラスター >%s< にアクセスできませんでした"

#: paxes_cinder/k2aclient/v1/paxes_manager.py:114
msgid "Check the PowerVC SharedStoragePool configuration"
msgstr "PowerVC SharedStoragePool 構成を確認してください"

#: paxes_cinder/k2aclient/v1/paxes_manager.py:115
#, python-format
msgid "SharedStoragePool: Couldn't access SharedStoragePool in Cluster: >%s<"
msgstr "SharedStoragePool: クラスター >%s< 内の SharedStoragePool にアクセスできませんでした"

#: paxes_cinder/k2aclient/v1/paxes_manager.py:117
#: paxes_cinder/k2aclient/v1/paxes_manager.py:122
#: paxes_cinder/k2aclient/v1/paxes_manager.py:127
#: paxes_cinder/k2aclient/v1/paxes_manager.py:133
msgid "Diagnose and repair Cluster"
msgstr "クラスターを診断して修復します"

#: paxes_cinder/k2aclient/v1/paxes_manager.py:118
#, python-format
msgid ""
"SharedStoragePool: Successfully accessed SharedStoragePool in Cluster: "
">%s<"
msgstr "SharedStoragePool: クラスター >%s< 内の SharedStoragePool に正常にアクセスしました"

#: paxes_cinder/k2aclient/v1/paxes_manager.py:120
#, python-format
msgid "SharedStoragePool: Unable to create LogicalUnits in Cluster: >%s<"
msgstr "SharedStoragePool: クラスター >%s< に LogicalUnit を作成できません"

#: paxes_cinder/k2aclient/v1/paxes_manager.py:123
#, python-format
msgid "SharedStoragePool: LogicalUnit creation functional in Cluster: >%s<"
msgstr "SharedStoragePool: クラスター >%s< での LogicalUnit の作成は機能しています"

#: paxes_cinder/k2aclient/v1/paxes_manager.py:125
#, python-format
msgid "SharedStoragePool: Unable to clone LogicalUnits in Cluster: >%s<"
msgstr "SharedStoragePool: クラスター >%s< に LogicalUnit を複製できません"

#: paxes_cinder/k2aclient/v1/paxes_manager.py:128
#, python-format
msgid ""
"SharedStoragePool: Unable to clone LogicalUnits in Cluster: >%s<, status:"
" >%s<"
msgstr "SharedStoragePool: クラスター >%s< に LogicalUnit を複製できません。状況: >%s<"

#: paxes_cinder/k2aclient/v1/paxes_manager.py:130
#, python-format
msgid "Clone functional in Cluster: >%s<"
msgstr "クラスター >%s< での複製は機能しています"

#: paxes_cinder/k2aclient/v1/paxes_manager.py:131
#, python-format
msgid "SharedStoragePool: Unable to delete LogicalUnits in Cluster: >%s<"
msgstr "SharedStoragePool: クラスター >%s< の LogicalUnit を削除できません"

#: paxes_cinder/k2aclient/v1/paxes_manager.py:134
#, python-format
msgid "SharedStoragePool: LogicalUnit deletion functional in Cluster: >%s<"
msgstr "SharedStoragePool: クラスター >%s< での LogicalUnit の削除は機能しています"

#: paxes_cinder/k2aclient/v1/paxes_manager.py:136
msgid "SharedStoragePool: Not Attempted"
msgstr "SharedStoragePool: 試行されていません"

#: paxes_cinder/k2aclient/v1/paxes_manager.py:143
msgid "HMC connectivity"
msgstr "HMC 接続"

#: paxes_cinder/k2aclient/v1/paxes_manager.py:144
msgid "Test connection to an HMC managing the SharedStoragePool"
msgstr "SharedStoragePool を管理している HMC への接続をテストします"

#: paxes_cinder/k2aclient/v1/paxes_manager.py:147
msgid "Cluster and SharedStoragePool accessibility"
msgstr "クラスターおよび SharedStoragePool のアクセス可能度"

#: paxes_cinder/k2aclient/v1/paxes_manager.py:148
msgid "Test the accessibility of a SharedStoragePool"
msgstr "SharedStoragePool のアクセス可能度をテストします"

#: paxes_cinder/k2aclient/v1/paxes_manager.py:151
msgid "Create SharedStoragePool LogicalUnits"
msgstr "SharedStoragePool LogicalUnit を作成します"

#: paxes_cinder/k2aclient/v1/paxes_manager.py:152
msgid "Test the capability to create SharedStoragePool LogicalUnits"
msgstr "SharedStoragePool LogicalUnit の作成機能をテストします"

#: paxes_cinder/k2aclient/v1/paxes_manager.py:155
msgid "Clone LogicalUnits"
msgstr "LogicalUnit を複製します"

#: paxes_cinder/k2aclient/v1/paxes_manager.py:156
msgid "Test the capability to perform a clone"
msgstr "複製の実行機能をテストします"

#: paxes_cinder/k2aclient/v1/paxes_manager.py:159
msgid "Delete SharedStoragePool LogicalUnits"
msgstr "SharedStoragePool LogicalUnit を削除します"

#: paxes_cinder/k2aclient/v1/paxes_manager.py:160
msgid "Test the capability to delete SharedStoragePool LogicalUnits"
msgstr "SharedStoragePool LogicalUnit の削除機能をテストします"

#: paxes_cinder/k2aclient/v1/sharedstoragepool_manager.py:112
#, python-format
msgid ""
"k2aclient: during updated_append_lus, cannot update K2 object(s) obtained"
" from a list operation, for ssp: >%s<"
msgstr ""
"NV-CEE080E k2aclient: updated_append_lus 中、リスト操作から取得した、ssp >%s< の K2 "
"オブジェクトを更新できません"

#: paxes_cinder/k2aclient/v1/sharedstoragepool_manager.py:158
#, python-format
msgid "k2aclient: during updated_append_lus, wrong length of lu input tuple: >%d<"
msgstr "NV-B8F5AF7 k2aclient: updated_append_lus 中、LU 入力タプルの長さに誤りがあります: >%d<"

#: paxes_cinder/k2aclient/v1/sharedstoragepool_manager.py:192
#, python-format
msgid ""
"k2aclient:  during updated_append_lus, request to add LU unit_name: >%s< "
"failed, name must be unique"
msgstr ""
"NV-F6B87FC k2aclient: updated_append_lus 中、LU unit_name >%s< "
"の追加要求が失敗しました。固有の名前でなければなりません"

#: paxes_cinder/k2aclient/v1/sharedstoragepool_manager.py:224
#, python-format
msgid ""
"k2aclient: during updated_append_lus, while adding LUs named: "
">%(lunames)s<,  # attempts due to HTTP 412 exceeded: "
">%(self.api.retries)d<"
msgstr ""
"NV-01A9381 k2aclient: updated_append_lus 中、>%(lunames)s< という名前の LU "
"を追加しているときに、HTTP 412 により、試行回数が超過しました: >%(self.api.retries)d<"

#: paxes_cinder/k2aclient/v1/sharedstoragepool_manager.py:260
#, python-format
msgid ""
"k2aclient: during updated_append_lus, cant handle K2 response, K2 "
"reported successful creation of >%(lenlus)d<  lus named: >%(lunames)s<,  "
"attempts: >%(attempts)d<  but only >%(lustoadd)d< LUs were found."
msgstr ""
"k2aclient: updated_append_lus の間に、K2 応答を処理できません。%(lenlus)d< 個の LU "
"が正常に作成されたことを K2 が報告しました。LU の名前: >%(lunames)s<。試行回数: >%(attempts)d<。見つかった "
"LU は >%(lustoadd)d< 個だけでした。"

#: paxes_cinder/k2aclient/v1/sharedstoragepool_manager.py:276
#, python-format
msgid ""
"k2aclient: during updated_append_lus, cant handle K2 response, K2 "
"reported successful creation of >%(lenlus)d< lus named: >%(lunames)s<, "
"attempts: >%(attempts)d< but >%(lustoadd)d< extra LUs were returned."
msgstr ""
"k2aclient: updated_append_lus 中、K2 応答を処理できません。K2 は >%(lenlus)d< 個の LU が "
">%(lunames)s< という名前で、>%(attempts)d< "
"回の試行で正常に作成されたことを報告しましたが、>%(lustoadd)d< 個の余分な LU が返されました。"

#: paxes_cinder/k2aclient/v1/sharedstoragepool_manager.py:369
#, python-format
msgid ""
"k2aclient: during update_append_lu, programming error, could not find "
"lu_udid: >%(lu_udid)s<, in input ssp for: >%(pool)s<"
msgstr ""
"k2aclient: update_append_lu 中、プログラミング・エラーが発生しました。lu_udid >%(lu_udid)s< "
"が、>%(pool)s< の入力 ssp 内で見つかりませんでした"

#: paxes_cinder/k2aclient/v1/sharedstoragepool_manager.py:390
#, python-format
msgid ""
"k2aclient: during update_append_lu, while deleting LUs w/ udids: "
">%(lu_udids)s<, # attempts due to HTTP 412 exceeded: >%(retries)d<"
msgstr ""
"NV-A3B2A22 k2aclient: update_append_lu の間、udid >%(lu_udids)s< の LU "
"を削除しているときに、HTTP 412 が原因で試行回数が >%(retries)d< 回を超えました。"

#: paxes_cinder/k2aclient/v1/shell.py:55
#, python-format
msgid "k2aclient: during encoding unexpected type: >%s<"
msgstr "NV-AA592CA k2aclient: 予期しないタイプをエンコードしている間: >%s<"

#: paxes_cinder/k2aclient/v1/shell.py:205
#: paxes_cinder/k2aclient/v1/shell.py:801
#: paxes_cinder/k2aclient/v1/shell.py:812
msgid "Id of the cluster."
msgstr "クラスターの ID。"

#: paxes_cinder/k2aclient/v1/shell.py:215
msgid "UUID of the cluster containing the LUs."
msgstr "LU が含まれるクラスターの UUID。"

#: paxes_cinder/k2aclient/v1/shell.py:218
msgid "UDID of the source logicalunit."
msgstr "ソース logicalunit の UDID。"

#: paxes_cinder/k2aclient/v1/shell.py:221
msgid "UDID of the destination logicalunit."
msgstr "宛先 logicalunit の UDID。"

#: paxes_cinder/k2aclient/v1/shell.py:231
msgid "Id of the managedsystem to list logicalpartitions"
msgstr "logicalpartition をリストする managedsystem の ID"

#: paxes_cinder/k2aclient/v1/shell.py:246
#: paxes_cinder/k2aclient/v1/shell.py:273
#: paxes_cinder/k2aclient/v1/shell.py:295
#: paxes_cinder/k2aclient/v1/shell.py:350
#: paxes_cinder/k2aclient/v1/shell.py:486
#: paxes_cinder/k2aclient/v1/shell.py:658
#: paxes_cinder/k2aclient/v1/shell.py:674
#: paxes_cinder/k2aclient/v1/shell.py:698
#: paxes_cinder/k2aclient/v1/shell.py:714
msgid "Id of the managedsystem."
msgstr "managedsystem の ID。"

#: paxes_cinder/k2aclient/v1/shell.py:249
#: paxes_cinder/k2aclient/v1/shell.py:262
#: paxes_cinder/k2aclient/v1/shell.py:617
#: paxes_cinder/k2aclient/v1/shell.py:634
msgid "Id of the logicalpartition."
msgstr "logicalpartition の ID。"

#: paxes_cinder/k2aclient/v1/shell.py:276
msgid "UDIDs of the logicalpartition."
msgstr "logicalpartition の UDID。"

#: paxes_cinder/k2aclient/v1/shell.py:313
#: paxes_cinder/k2aclient/v1/shell.py:324
#: paxes_cinder/k2aclient/v1/shell.py:347
msgid "Id of the managementconsole."
msgstr "managementconsole の ID。"

#: paxes_cinder/k2aclient/v1/shell.py:327
#: paxes_cinder/k2aclient/v1/shell.py:356
msgid "Command to run."
msgstr "実行するコマンド。"

#: paxes_cinder/k2aclient/v1/shell.py:353
msgid "UUID of the virtualioserver."
msgstr "virtualioserver の UUID。"

#: paxes_cinder/k2aclient/v1/shell.py:394
msgid "Id of the sharedstoragepool."
msgstr "sharedstoragepool の ID。"

#: paxes_cinder/k2aclient/v1/shell.py:405
#: paxes_cinder/k2aclient/v1/shell.py:443
#: paxes_cinder/k2aclient/v1/shell.py:456
msgid "UUID of the sharedstoragepool."
msgstr "sharedstoragepool の UUID。"

#: paxes_cinder/k2aclient/v1/shell.py:408
msgid "Name of the new logicalunit."
msgstr "新規 logicalunit の名前。"

#: paxes_cinder/k2aclient/v1/shell.py:411
msgid "Capacity of the new logicalunit."
msgstr "新規 logicalunit の容量。"

#: paxes_cinder/k2aclient/v1/shell.py:414
msgid "Optional flag to control whether the new logicalunit will be thick or thin"
msgstr "新規 logicalunit がシックかシンかを制御するオプションのフラグ"

#: paxes_cinder/k2aclient/v1/shell.py:419
msgid "LogicalUnitType: VirtualIO_Disk | VirtualIO_Image"
msgstr "LogicalUnitType: VirtualIO_Disk | VirtualIO_Image"

#: paxes_cinder/k2aclient/v1/shell.py:423
msgid "Optional udid of LU to clone from, new if omitted"
msgstr "オプションの複製元 LU の UDID。省略した場合は、新規になります"

#: paxes_cinder/k2aclient/v1/shell.py:446
msgid "UDIDs of the logicalunit."
msgstr "logicalunit の UDID。"

#: paxes_cinder/k2aclient/v1/shell.py:459
msgid "Optional flag to control whether full details should be output"
msgstr "完全な詳細を出力するかどうかを制御するオプションのフラグ"

#: paxes_cinder/k2aclient/v1/shell.py:471
msgid "Id of the managedsystem to list virtualioservers"
msgstr "virtualioserver をリストする managedsystem の ID"

#: paxes_cinder/k2aclient/v1/shell.py:489
#: paxes_cinder/k2aclient/v1/shell.py:513
msgid "Id of the virtualioserver."
msgstr "virtualioserver の ID。"

#: paxes_cinder/k2aclient/v1/shell.py:493
msgid ""
"Optional extended attributes Valid values include: All, Advanced, "
"Hypervisor, SystemNetwork, ViosStorage, ViosNetwork, ViosFCMapping, "
"ViosSCSIMapping, and None May be used multiple times. \"All\" if omitted"
msgstr ""
"オプションの拡張属性として有効な値には、All、Advanced、Hypervisor、SystemNetwork, "
"ViosStorage、ViosNetwork、ViosFCMapping、ViosSCSIMapping、None があり、None "
"は複数回使用されることがあります。省略した場合は、「All」になります"

#: paxes_cinder/k2aclient/v1/shell.py:608
msgid "Id of the logicalpartition to list clientnetworkadapters"
msgstr "clientnetworkadapter をリストする logicalpartition の ID"

#: paxes_cinder/k2aclient/v1/shell.py:620
msgid "Id of the clientnetworkadapter."
msgstr "clientnetworkadapter の ID。"

#: paxes_cinder/k2aclient/v1/shell.py:637
msgid "UDIDs of the clientnetworkadapter."
msgstr "clientnetworkadapter の UDID。"

#: paxes_cinder/k2aclient/v1/shell.py:649
msgid "Id of the managedsystem to list virtualnetworks"
msgstr "virtualnetwork をリストする managedsystem の ID"

#: paxes_cinder/k2aclient/v1/shell.py:661
msgid "Id of the virtualnetwork."
msgstr "virtualnetwork の ID。"

#: paxes_cinder/k2aclient/v1/shell.py:677
msgid "UDIDs of the virtualnetwork."
msgstr "virtualnetwork の UDID。"

#: paxes_cinder/k2aclient/v1/shell.py:689
msgid "Id of the managedsystem to list virtualswitchs"
msgstr "virtualswitch をリストする managedsystem の ID"

#: paxes_cinder/k2aclient/v1/shell.py:701
msgid "Id of the virtualswitch."
msgstr "virtualswitch の ID。"

#: paxes_cinder/k2aclient/v1/shell.py:717
msgid "UDIDs of the virtualswitch."
msgstr "virtualswitch の UDID。"

#: paxes_cinder/k2aclient/v1/shell.py:740
msgid "Id of the file."
msgstr "ファイルの ID。"

#: paxes_cinder/k2aclient/v1/shell.py:750
msgid "Ids of the files."
msgstr "ファイルの ID。"

#: paxes_cinder/k2aclient/v1/shell.py:761
msgid "/rest/api/uom<uomresource>."
msgstr "/rest/api/uom<uomresource>。"

#: paxes_cinder/k2aclient/v1/shell.py:766
msgid "Send output to file"
msgstr "出力をファイルに送信します"

#: paxes_cinder/k2aclient/v1/shell.py:782
msgid "Read cinder ssp conf files and report on health"
msgstr "cinder ssp 構成ファイルを読み取り、正常性について報告します"

#: paxes_cinder/k2aclient/v1/shell.py:815
#: paxes_cinder/k2aclient/v1/shell.py:843
msgid "VIOS password for all VIOS defaults to \"padmin\""
msgstr "すべての VIOS の VIOS パスワードは、デフォルトの「padmin」になります。"

#: paxes_cinder/k2aclient/v1/shell.py:820
#: paxes_cinder/k2aclient/v1/shell.py:848
msgid "Target directory for snapsdefaults to \"/tmp/vios-snap\""
msgstr "スナップのターゲット・ディレクトリーは、デフォルトの「/tmp/vios-snap」になります。"

#: paxes_cinder/k2aclient/v1/shell.py:839
msgid "list of vios ips expressed as jsoneg '[\"9.47.161.157\"]'"
msgstr "VIOS IP のリストは、jsoneg '[\"9.47.161.157\"]' と表されます。"

#: paxes_cinder/k2aclient/v1/v1k2creater.py:170
#, python-format
msgid "k2aclient: during process_root, unrecognized service: >%s<"
msgstr "NV-1FC12D8 k2aclient: process_root 中、認識されないサービス: >%s<"

#: paxes_cinder/k2aclient/v1/v1k2loader.py:61
#, python-format
msgid ""
"k2aclient: during k2 deserialization, for type: >%(pcname)s<, k2 gave "
"unknown attr: >%(us_tag)s<, is there a schema mismatch?, will skip ..."
msgstr ""
"NV-A18BFC5 k2aclient: k2 非直列化中、タイプ >%(pcname)s< に対して、k2 が不明な属性 "
">%(us_tag)s< を指定しました。スキーマが一致していない可能性があります。スキップします..."

#: paxes_cinder/k2aclient/v1/v1k2loader.py:77
#, python-format
msgid ""
"k2aclient: during k2 deserialization, for type: >%(pcname)s<, k2 attr: "
">%(us_tag)s<: is listed as scalar, but maybe its not?, is there a schema "
"mismatch?, will replace existing scalar w/ next value ..."
msgstr ""
"k2aclient: k2 非直列化中、タイプ >%(pcname)s< に対して、k2 属性 >%(us_tag)s< "
"がスカラーとしてリストされていますが、スカラーではない可能性およびスキーマが一致していない可能性があります。既存のスカラーを次の値で置き換えます..."

#: paxes_cinder/k2aclient/v1/v1k2loader.py:131
#, python-format
msgid ""
"k2aclient: during k2 deserialization, while processing: k2 type: "
">%(parent_tag)s<, there is no definition for k2 type: >%(k2type)s<, is "
"there a schema mismatch?, will skip ..."
msgstr ""
"k2aclient: k2 非直列化中、k2 タイプ >%(parent_tag)s< を処理しているときに、k2 タイプ "
">%(k2type)s< の定義がありません。スキーマが一致していない可能性があります。スキップします..."

#: paxes_cinder/k2aclient/v1/v1k2loader.py:190
#: paxes_cinder/k2aclient/v1/v1k2loader.py:199
msgid "k2aclient:"
msgstr "NV-E561712 k2aclient:"

#: paxes_cinder/k2aclient/v1/virtualioserver_manager.py:280
#, python-format
msgid ""
"k2aclient: during lua_recovery, for device_id: >%(device_id)s<, "
"experienced job failure, job_id: >%(jresponse.job_id)s<, status: "
">%(jresponse.status)s<, input K2 job diagnostics have been written to: "
">%(diagfspeci)s<, response k2 job diagnostics have been written to: "
">%(diagfspec)s<"
msgstr ""
"k2aclient: lua_recovery の間に、device_id >%(device_id)s< "
"でジョブ障害が発生しました。job_id: >%(jresponse.job_id)s<、状況: "
">%(jresponse.status)s<。入力 K2 ジョブ診断が >%(diagfspeci)s< に書き込まれました。応答 k2 "
"ジョブ診断が >%(diagfspec)s< に書き込まれました。"

#: paxes_cinder/k2aclient/v1/web_file_manager.py:83
msgid ""
"k2aclient: during file upload, filename: >%(wf.filename)s<, id: "
">%(wf.id)s<, file_uuid: >%(wf.file_uuid)s<, file_enum_type: "
">%(wf.file_enum_type)s<"
msgstr ""
"k2aclient: ファイルのアップロード中。ファイル名: >%(wf.filename)s<、ID: "
">%(wf.id)s<、file_uuid: >%(wf.file_uuid)s<、file_enum_type: "
">%(wf.file_enum_type)s<"

#: paxes_cinder/k2aclient/v1/web_job_manager.py:65
#, python-format
msgid ""
"k2aclient: during %(jobtype)s, retry job, job_id: >%(job_id)s<, status: "
">%(status)s<,"
msgstr ""
"NV-FBECCFD k2aclient: %(jobtype)s の間に、ジョブを再試行します。job_id: >%(job_id)s<、状況:"
" >%(status)s<。"

#: paxes_cinder/k2aclient/v1/web_job_manager.py:77
#, python-format
msgid ""
"k2aclient: during %(jobtype)s, too many retries, maximum number of "
"retries: >%(maxretries)d<, job_id: >%(job_id)s<, status: >%(status)s<,"
msgstr ""
"k2aclient: %(jobtype)s の間に、再試行回数が多すぎます。再試行の最大回数: >%(maxretries)d<、job_id:"
" >%(job_id)s<、状況: >%(status)s<。"

#: paxes_cinder/scheduler/host_manager.py:59
#, python-format
msgid "clean up host_state_map: %(host)shost"
msgstr "NV-F9D1534 host_state_map のクリーンアップ: %(host)s ホスト"

#: paxes_cinder/scheduler/sched_drv.py:56
#, python-format
msgid "volume request: requested size: %(size)s. "
msgstr "ボリュームの要求: 要求サイズ: %(size)s。 "

#: paxes_cinder/scheduler/sched_drv.py:62
#, python-format
msgid ""
"{host: %(hostname)s, free_capacity: %(free_cap)s, total_capacity: "
"%(total)s, reserved_percentage: %(reserved)s, last update: "
"%(time_updated)s}"
msgstr ""
"{ホスト: %(hostname)s、free_capacity: %(free_cap)s、total_capacity: "
"%(total)s、reserved_percentage: %(reserved)s、最終更新: %(time_updated)s}"

#: paxes_cinder/scheduler/sched_drv.py:72
msgid "request exceeds capacity: info"
msgstr "NV-DBCC600 要求が容量を超えています: 情報"

#: paxes_cinder/scheduler/sched_drv.py:75
msgid "No storage has been registered. "
msgstr "NV-96E101B ストレージは登録されていません。"

#: paxes_cinder/scheduler/filters/paxes_capacity_filter.py:67
msgid ""
"Free capacity not set: Volume node is either still under initialization "
"or the node info collection is broken."
msgstr "NV-872554F 空き容量が設定されていません: ボリューム・ノードがまだ初期化中であるか、ノード情報の収集が中断しています。"

#: paxes_cinder/scheduler/filters/paxes_capacity_filter.py:99
msgid "missing default_volume_type"
msgstr "NV-404930C default_volume_type がありません"

#: paxes_cinder/scheduler/filters/paxes_capacity_filter.py:106
#, python-format
msgid ""
"missing valid rsize on                                 "
"%(default)svolume_type: %(vol_type)s"
msgstr ""
"NV-B717E15 有効な rsize がありません:                                "
"%(default)svolume_type: %(vol_type)s"

#: paxes_cinder/scheduler/filters/paxes_capacity_filter.py:117
#, python-format
msgid ""
"Insufficient free space for volume creation (requested / avail / rsize): "
"%(requested)s/%(available)s/%(rsize)s"
msgstr ""
"NV-5CC98A1 ボリューム作成用のフリー・スペースが不足しています (要求された量/使用可能な量/rsize): "
"%(requested)s/%(available)s/%(rsize)s"

#: paxes_cinder/scheduler/filters/paxes_capacity_filter.py:124
#, python-format
msgid ""
"Sufficient free space for volume creation (requested / avail / rsize): "
"%(requested)s/%(available)s/%(rsize)s"
msgstr ""
"NV-D0E32D8 ボリューム作成用に十分なフリー・スペースがあります (要求された量/使用可能な量/rsize): "
"%(requested)s/%(available)s/%(rsize)s"

#: paxes_cinder/scohack/scohack_http.py:150
#, python-format
msgid "BadStoreUri: credentials '%(creds)s' not well-formatted."
msgstr "NV-5991AD7 BadStoreUri: 資格情報 '%(creds)s' の形式が正しくありません。"

#: paxes_cinder/scohack/scohack_http.py:160
msgid "BadStoreUri: no address specified in HTTP URL"
msgstr "NV-2A5D3E2 BadStoreUri: HTTP URL にアドレスが指定されていません"

#: paxes_cinder/scohack/scohack_http.py:295
#, python-format
msgid "MaxRedirectsExceeded: redirects: >%(max)d<"
msgstr "NV-30617DF MaxRedirectsExceeded: リダイレクト数: >%(max)d<"

#: paxes_cinder/scohack/scohack_http.py:308
#, python-format
msgid "HTTP URL returned a %(status)s status code."
msgstr "HTTP URL で %(status)s 状況コードが返されました。"

#: paxes_cinder/scohack/scohack_http.py:310
#: paxes_cinder/scohack/scohack_http.py:322
#, python-format
msgid "BadStoreUri: loc.path: >%(path)s<, reason: >%(reason)s<"
msgstr "NV-0E3AB46 BadStoreUri: loc.path: >%(path)s<、理由: >%(reason)s<"

#: paxes_cinder/scohack/scohack_location.py:50
#, python-format
msgid "exception.UnknownScheme: scheme: >%(scheme)s<"
msgstr "NV-B8DA628 exception.UnknownScheme: スキーム: >%(scheme)s<"

#: paxes_cinder/scohack/scohack_scohack.py:77
msgid "URI must start with scohack://"
msgstr "NV-DF4522D URI の先頭には scohack:// を使用する必要があります"

#: paxes_cinder/scohack/scohack_scohack.py:79
#, python-format
msgid "BadStore: uri: >%(uri)s<, reason: >%(reason)s<"
msgstr "NV-7D2A4E2 BadStore: uri: >%(uri)s<、理由: >%(reason)s<"

#: paxes_cinder/scohack/scohack_scohack.py:93
#, python-format
msgid "x-scg-vios-id: >%(id)s< not of form 'ttttmmm_sssssssnnn'"
msgstr "NV-9CCE26B x-scg-vios-id: >%(id)s< の形式が 'ttttmmm_sssssssnnn' ではありません"

#: paxes_cinder/scohack/scohack_scohack.py:106
#, python-format
msgid "scohack: x-scg-vios-id: cant list ManagedSystem: >%(ex)s<"
msgstr "NV-405AA27 scohack: x-scg-vios-id: ManagedSystem をリストできません: >%(ex)s<"

#: paxes_cinder/scohack/scohack_scohack.py:121
#, python-format
msgid "scohack: x-scg-vios-id: cant find ManagedSystem for: >%(id)s<"
msgstr "NV-708F8BE scohack: x-scg-vios-id: >%(id)s< の ManagedSystem が見つかりません"

#: paxes_cinder/scohack/scohack_scohack.py:129
#, python-format
msgid "scohack: x-scg-vios-id: cant list VirtualIoServer: >%(ex)s<"
msgstr "NV-2D6AE0A scohack: x-scg-vios-id: VirtualIoServer をリストできません: >%(ex)s<"

#: paxes_cinder/scohack/scohack_scohack.py:139
#, python-format
msgid "scohack: x-scg-vios-id: cant find VirtualIOServer for: >%(id)s<"
msgstr "NV-081426D scohack: x-scg-vios-id: >%(id)s< の VirtualIOServer が見つかりません"

#: paxes_cinder/scohack/scohack_scohack.py:162
msgid "scohack: cant list vios"
msgstr "NV-D40CA86 scohack: vios をリストできません"

#: paxes_cinder/scohack/scohack_scohack.py:168
msgid "scohack: no vios found"
msgstr "NV-ABFCCCD scohack: vios が見つかりません"

#: paxes_cinder/scohack/scohack_scohack.py:177
#, python-format
msgid "scohack: cant list vios for ms: >%(id)s<"
msgstr "NV-D6ED6BF scohack: ms >%(id)s< の vios をリストできません"

#: paxes_cinder/scohack/scohack_scohack.py:184
#, python-format
msgid "scohack: no vios found for ms: >%(id)s<"
msgstr "NV-0FD0B8A scohack: ms >%(id)s< の vios が見つかりません"

#: paxes_cinder/scohack/scohack_scohack.py:195
#, python-format
msgid "scohack: for ms: >%(mid)s<, cant find vios: >%(vid)s<"
msgstr "NV-AD83B35 scohack: ms >%(mid)s< の vios >%(vid)s< が見つかりません"

#: paxes_cinder/scohack/scohack_scohack.py:204
#, python-format
msgid "scohack: cant find vios: >%(vid)s<"
msgstr "NV-3704F44 scohack: vios >%(vid)s< が見つかりません"

#: paxes_cinder/scohack/scohack_scohack.py:328
#, python-format
msgid ""
"scohack: only single hmc is supported: prev: >%(prev_id)s<, new: "
">%(new_id)s<"
msgstr "NV-185C13E scohack: 1 つの hmc のみがサポートされます。旧: >%(prev_id)s<、新: >%(new_id)s<"

#: paxes_cinder/scohack/scohack_scohack.py:339
#, python-format
msgid "scohack: no HMC for id: >%(id)s<"
msgstr "NV-628D2F6 scohack: id >%(id)s< 用の HMC がありません"

#: paxes_cinder/scohack/scohack_scohack.py:352
#, python-format
msgid ""
"scohack: managemenconsole: >%(mc)s< could not be retrieved, hdisks will "
"not be cleaned up, msg: >%(msg)s<"
msgstr ""
"scohack: managemenconsole >%(mc)s< を取得できませんでした。hdisk はクリーンアップされません。メッセージ:"
" >%(msg)s<"

#: paxes_cinder/scohack/scohack_scohack.py:383
#, python-format
msgid "scohack: vios: >%(vios)s<, volume: >%(vol)s<"
msgstr "NV-22A4C11 scohack: vios: >%(vios)s<、ボリューム: >%(vol)s<"

#: paxes_cinder/scohack/scohack_scohack.py:400
#, python-format
msgid "scohack: image upload: hdisk: >%(hdisk)s<, vios: >%(vios)s<"
msgstr "NV-B86BF01 scohack: イメージのアップロード: hdisk: >%(hdisk)s<、vios: >%(vios)s<"

#: paxes_cinder/scohack/scohack_scohack.py:417
#, python-format
msgid "scohack: volume not found: >%(volume)s<"
msgstr "NV-CDC6DBB scohack: ボリュームが見つかりません: >%(volume)s<"

#: paxes_cinder/scohack/scohack_scohack.py:428
#, python-format
msgid "scohack: volume: invalid status: >%(status)s<"
msgstr "NV-D365509 scohack: ボリューム: 無効な状況: >%(status)s<"

#: paxes_cinder/scohack/scohack_scohack.py:445
#, python-format
msgid "scohack: no ports for vios: >%(vios)s<"
msgstr "NV-230F42F scohack: vios >%(vios)s< 用のポートがありません"

#: paxes_cinder/scohack/scohack_scohack.py:461
#, python-format
msgid "scohack: failed to connect to volume >%(volume_id)s< "
msgstr "NV-E7095A2 scohack: ボリューム >%(volume_id)s< への接続に失敗しました "

#: paxes_cinder/scohack/scohack_scohack.py:471
#, python-format
msgid ""
"scohack: for target volume: >%(volume)s<, bad connection: >%(info)s<, no "
"target_lun"
msgstr ""
"NV-79C5617 scohack: 宛先ボリューム >%(volume)s< に対して接続が正しくありません: "
">%(info)s<。target_lun がありません"

#: paxes_cinder/scohack/scohack_scohack.py:487
#, python-format
msgid ""
"scohack: for target volume: >%(volume)s<, no target wwpn found in "
"connection: >%(info)s< "
msgstr "NV-5C2B384 scohack: 宛先ボリューム >%(volume)s< の宛先 wwpn が接続に見つかりません: >%(info)s< "

#: paxes_cinder/scohack/scohack_scohack.py:506
#, python-format
msgid "scohack: target volume: >%(volume)s<, does not have page83 data"
msgstr "NV-33E8084 scohack: 宛先ボリューム >%(volume)s< に page83 データがありません"

#: paxes_cinder/scohack/scohack_scohack.py:514
#, python-format
msgid "scohack: start luarecovery: deviceid: >%(id)s< , itls: >%(itls)s<"
msgstr ""
"NV-0A59DDD scohack: luarecovery を開始します: deviceid: >%(id)s<、itls: "
">%(itls)s<"

#: paxes_cinder/scohack/scohack_scohack.py:525
#, python-format
msgid "scohack: lua_recovery job failed for target volume: >%(volume)s<"
msgstr "NV-D94C9A2 scohack: lua_recovery ジョブが宛先ボリューム >%(volume)s< で失敗しました"

#: paxes_cinder/scohack/scohack_scohack.py:538
#, python-format
msgid "scohack: luarcovery job status: >%(status)s<, result: >%(res)s<"
msgstr "NV-FC7E239 scohack: luarcovery ジョブ状況: >%(status)s<、結果: >%(res)s<"

#: paxes_cinder/scohack/scohack_scohack.py:544
#, python-format
msgid ""
"scohack: lua_recovery job internal error, device_list is invalid device "
"list: >%(lua_list)s<"
msgstr ""
"NV-610160F scohack: lua_recovery ジョブの内部エラー。device_list は無効なデバイス・リストです: "
">%(lua_list)s<"

#: paxes_cinder/scohack/scohack_scohack.py:552
#, python-format
msgid ""
"scohack: lua_recovery job returned multiple devices device list: "
">%(lua_list)s<, will select first ..."
msgstr ""
"NV-3A4481D scohack: lua_recovery ジョブが複数デバイスのデバイス・リストを返しました: "
">%(lua_list)s<。最初のリストが選択されます..."

#: paxes_cinder/scohack/scohack_scohack.py:562
#, python-format
msgid ""
"This means that a device was found from an ITL nexus and it was "
"determined to be in use by the VIOS. The most likely cause is that a "
"virtual device was not removed from a previous deploy. The VIOS took no "
"action in this case. device: >%(dev)s<"
msgstr ""
"これは、ITL nexus からデバイスが見つかったこと、およびそのデバイスは VIOS "
"によって使用中であるものと判別されたことを意味します。可能性が高い原因として、仮想デバイスが以前のデプロイから削除されなかったことが考えられます。この場合、VIOS"
" によるアクションは行われません。デバイス: >%(dev)s<"

#: paxes_cinder/scohack/scohack_scohack.py:572
#, python-format
msgid ""
"This means that the ITL nexus is not consider reliable and some error "
"occurred that prevents the VIOS from determining making a decision on "
"safely removing a device. The VIOS took no action in this case. Perhaps "
"try to remove the offending hdisk from the VIOS, with rmdev -d -l hdiskx."
" device: >%(dev)s<"
msgstr ""
"NV-DC7D321 これは、ITL nexus が、信頼できる対象として見なされないこと、およびデバイスを安全に削除できるかどうかを VIOS "
"側で決定できない何らかのエラーが発生したことを意味します。この場合、VIOS によるアクションは行われません。可能であれば、rmdev -d -l"
" hdiskx を使用して、問題の hdisk を VIOS から削除してみてください。デバイス: >%(dev)s<"

#: paxes_cinder/scohack/scohack_scohack.py:585
#, python-format
msgid ""
"This means the information provided and action taken by the VIOS was "
"sufficient to find the storage. pvName, and uniqueID elements will follow"
" in the data stream. device: >%(dev)s<"
msgstr ""
"NV-8DB8D33 これは、指定された情報と、VIOS "
"によって実行されたアクションが、ストレージを検出する上で十分なものであったことを意味します。データ・ストリームで、この後に pvName "
"エレメントと uniqueID エレメントが続きます。デバイス: >%(dev)s<"

#: paxes_cinder/scohack/scohack_scohack.py:593
#, python-format
msgid ""
"This means some new storage element was found at the ITL nexus but VIOS "
"could not determine if it is the storage of interest to the management "
"tool. device: >%(dev)s<"
msgstr ""
"NV-36ADD00 これは、新規ストレージ・エレメントが ITL nexus で見つかったものの、VIOS "
"ではそれが管理ツールの対象ストレージであるかどうかを判別できなかったことを意味します。デバイス: >%(dev)s<"

#: paxes_cinder/scohack/scohack_scohack.py:602
#, python-format
msgid ""
"The VIOS could not determine if this is logical unit of interest to the "
"management tool however did find a device from the ITL nexus list. "
"device: >%(dev)s<"
msgstr ""
"NV-6761BFF VIOS ではこれが管理ツールの対象論理装置であるかどうかを判別できませんでしたが、ITL nexus "
"リストからのデバイスを検出しました。デバイス: >%(dev)s<"

#: paxes_cinder/scohack/scohack_scohack.py:611
#, python-format
msgid ""
"The VIOS could not find a device from the itl nexus list. It could be "
"some SCSI or transport error occurred during configuration or the ITL "
"nexus list was incorrect. device: >%(dev)s<"
msgstr ""
"NV-2479600 VIOS では、ITL nexus リストからのデバイスを検出できませんでした。構成中に SCSI "
"エラーまたはトランスポート・エラーが発生した可能性があります。または、ITL nexus リストが正しくありませんでした。デバイス: "
">%(dev)s<"

#: paxes_cinder/scohack/scohack_scohack.py:622
#, python-format
msgid ""
"Unknown device status. Severe internal error contact NCO. device: "
">%(dev)s<"
msgstr "NV-2EF1D11 不明なデバイス状況。重大な内部エラー。NCO にお問い合わせください。デバイス: >%(dev)s<"

#: paxes_cinder/scohack/scohack_scohack.py:638
#, python-format
msgid "scohack: failed to find device name: >%(dev)s<"
msgstr "NV-B6E8402 scohack: デバイス名 >%(dev)s< が見つかりませんでした"

#: paxes_cinder/scohack/scohack_scohack.py:643
#, python-format
msgid "scohack: found device name: >%(dev)s<"
msgstr "NV-32CF4C2 scohack: デバイス名 >%(dev)s< が見つかりました"

#: paxes_cinder/scohack/scohack_scohack.py:665
#, python-format
msgid "scohack: hdisk_uuid: >%(hdisk)s<, checksum not specified"
msgstr "NV-D85ABDC scohack: hdisk_uuid: >%(hdisk)s<、チェックサムが指定されていません"

#: paxes_cinder/scohack/scohack_scohack.py:672
#, python-format
msgid "scohack: hdisk_uuid: >%(hdisk)s<, size not specified"
msgstr "NV-9783CB3 scohack: hdisk_uuid: >%(hdisk)s<、サイズが指定されていません"

#: paxes_cinder/scohack/scohack_scohack.py:694
#, python-format
msgid ""
"scohack: image upload complete for hdisk_uuid: >%(hdisk)s<, webfile id: "
">%(wid)s<, actual size: >%(size)s< bytes, elapsed time: >%(time)d< "
"seconds, rate: >%(rate)f< minutes/GB"
msgstr ""
"scohack: 以下のイメージのアップロードが完了しました: hdisk_uuid: >%(hdisk)s<、web ファイル ID: "
">%(wid)s<、実際のサイズ: >%(size)s< バイト、経過時間: >%(time)d< 秒、速度: >%(rate)f< 分/GB"

#: paxes_cinder/scohack/scohack_scohack.py:709
#, python-format
msgid ""
"scohack:  mismatch: expected_file_size_in_bytes: >%e_size)d<, "
"current_file_size_in_bytes: >%(c_size)d<"
msgstr ""
"NV-E2ACA08 scohack: 不一致: expected_file_size_in_bytes: "
">%e_size)d<、current_file_size_in_bytes: >%(c_size)d<"

#: paxes_cinder/scohack/scohack_scohack.py:740
#, python-format
msgid ""
"scohack: cleanup failure for: >%(hdisk)s<, job status: >%(status)s<, "
"response: >%(res)s< continuing ..."
msgstr ""
"NV-C9A426B scohack: %(hdisk)s< でクリーンアップ障害。ジョブ状況: >%(status)s<。応答: "
">%(res)s<。続行します..."

#: paxes_cinder/scohack/scohack_scohack.py:752
#, python-format
msgid ""
"scohack: for hdisk_uuid: >%(hdisk)s<  no managementconsole, hisks will "
"not be cleaned up"
msgstr ""
"NV-508BE83 scohack: hdisk_uuid >%(hdisk)s< の managementconsole "
"がありません。hdisk はクリーンアップされません"

#: paxes_cinder/scohack/scohack_scohack.py:758
#: paxes_cinder/scohack/scohack_scohack.py:768
#, python-format
msgid "scohack: for hdisk_uuid: >%(hdisk)s< cleanup failed, msg: >%(ex)s<"
msgstr "NV-B37BCB5 scohack: hdisk_uuid >%(hdisk)s< でクリーンアップが失敗しました。メッセージ: >%(ex)s<"

#: paxes_cinder/scohack/scohack_scohack.py:772
#, python-format
msgid "scohack: upload failed for hdisk_uuid: >%(dsk)s<"
msgstr "NV-D7A600C scohack: hdisk_uuid でアップロードが失敗しました: >%(dsk)s<"

#: paxes_cinder/scohack/scohack_utils.py:47
#, python-format
msgid "Error: cooperative_iter exception %(error)s"
msgstr "NV-23E8986 エラー: cooperative_iter 例外 %(error)s"

#: paxes_cinder/volume/__init__.py:46
#, python-format
msgid ""
"cinder volume_create interface has been changed. PowerVC monkey patch for"
" volume clone won't work. function: %(fx)s, arguments: %(args)s"
msgstr ""
"NV-7A6F9A4 cinder volume_create インターフェースが変更されました。複製ボリュームに対する PowerVC "
"モンキー・パッチは動作しません。関数: %(fx)s、引数: %(args)s"

#: paxes_cinder/volume/__init__.py:61
#, python-format
msgid ""
"Monkey patched volume clone by paxes volume_create_decorator(). Source "
"Volume ID: %(svol)s, volume type name: %(voltpnm)s, volume type ID: "
"%(voltpid)s"
msgstr ""
"NV-D17192A paxes volume_create_decorator() "
"によって、複製ボリュームにモンキー・パッチが適用されました。ソース・ボリューム ID: %(svol)s、ボリューム・タイプ名: "
"%(voltpnm)s、ボリューム・タイプ ID: %(voltpid)s"

#: paxes_cinder/volume/__init__.py:94
#, python-format
msgid ""
"Failed to get the parameters from function "
"cinder.volume.volume_types.create(). Default quota didn't set for the "
"storage template. Error: %(err)s"
msgstr ""
"NV-A4934EA 関数 cinder.volume.volume_types.create() "
"からパラメーターを取得できませんでした。ストレージ・テンプレートに対してデフォルトの割り当て量が設定されていませんでした。エラー: %(err)s"

#: paxes_cinder/volume/__init__.py:114
#, python-format
msgid "Successfully set default quota for storage template %(vol_type)s"
msgstr "NV-71868FF ストレージ・テンプレート %(vol_type)s に対してデフォルトの割り当て量が正常に設定されました"

#: paxes_cinder/volume/__init__.py:118
#, python-format
msgid ""
"Failed to set default quota for storage template %(vol_type)s, error: "
"%(err)s"
msgstr ""
"NV-D86E5F7 ストレージ・テンプレート %(vol_type)s に対してデフォルトの割り当て量を設定できませんでした。エラー: "
"%(err)s"

#: paxes_cinder/volume/__init__.py:122
#, python-format
msgid ""
"Cannot set default quota for storage template %(vol_type) due to invalid "
"Parameters from volume type create."
msgstr ""
"NV-D9BA448 ボリューム・タイプ作成での無効なパラメーターが原因で、ストレージ・テンプレート %(vol_type)  "
"に対してデフォルトの割り当て量を設定できません。"

#: paxes_cinder/volume/__init__.py:175
#, python-format
msgid "Error getting data volumes: %s "
msgstr "NV-7627301 データ・ボリュームの取得中にエラーが発生しました: %s "

#: paxes_cinder/volume/manager.py:89
#, python-format
msgid "Cannot perform direct SAN operation on disk with prefix %(prefix)s"
msgstr "NV-1701BDD プレフィックス %(prefix)s を使用するディスクに対して、直接 SAN 操作を実行することはできません"

#: paxes_cinder/volume/manager.py:100
msgid "Driver still initializing, wait..."
msgstr "NV-C6CA9E0 ドライバーは現在初期化中です。お待ちください..."

#: paxes_cinder/volume/manager.py:102
#, python-format
msgid "Try again: %s"
msgstr "NV-FEE7BD0 再試行してください: %s"

#: paxes_cinder/volume/manager.py:172
#, python-format
msgid "Fabric {fabric_name} ({user}@{ip}:{port}): %(message)s"
msgstr "NV-0A01336 ファブリック {fabric_name} ({user}@{ip}:{port}): %(message)s"

#: paxes_cinder/volume/manager.py:188
#, python-format
msgid ""
"Storage Provider {storage_provider_hostname} ({user}@{ip}:{port}) "
"{volume_id}: %(message)s"
msgstr ""
"NV-E1A972C ストレージ・プロバイダー {storage_provider_hostname} ({user}@{ip}:{port}) "
"{volume_id}: %(message)s"

#: paxes_cinder/volume/manager.py:223
msgid ""
"The volume is already attached to another virtual server, possibly one "
"that is not managed by PowerVC."
msgstr "このボリュームは、既に別の仮想サーバーに接続されています。PowerVC によって管理されていないボリュームである可能性があります。"

#: paxes_cinder/volume/manager.py:227
msgid ""
"The volume cannot be deleted because it is either mapped to a host or "
"part of a flashcopy or remote copy operation."
msgstr "このボリュームは、ホストにマップされているか、FlashCopy 操作またはリモート・コピー操作の一部になっているため、削除できません。"

#: paxes_cinder/volume/manager.py:239
#, python-format
msgid "%(error_prefix)s failure for volume {volume_id}: %(error)s"
msgstr "ボリューム {volume_id} に対する %(error_prefix)s 失敗: %(error)s"

#: paxes_cinder/volume/manager.py:244
#, python-format
msgid ""
"%(error_prefix)s failure for volume {volume_id}.Command %(cmd)s, error "
"%(error)s"
msgstr "ボリューム {volume_id} に対する %(error_prefix)s 失敗。コマンド %(cmd)s、エラー %(error)s"

#: paxes_cinder/volume/manager.py:393
#, python-format
msgid "Resuming deletion of volume %s"
msgstr "NV-E253654 ボリューム %s の削除を再開中"

#: paxes_cinder/volume/manager.py:396
#, python-format
msgid ""
"Failed to delete volume %(volid)s during volume service startup. Error: "
"%(error)s"
msgstr "NV-CCA27AC ボリューム・サービスの起動時に、ボリューム %(volid)s を削除できませんでした。エラー: %(error)s"

#: paxes_cinder/volume/manager.py:410
#, python-format
msgid "Processing volume that was left in the attaching state. Volume id: %(id)s"
msgstr "NV-89FC9B0 接続状態になっていたボリュームの処理中です。ボリューム ID: %(id)s"

#: paxes_cinder/volume/manager.py:483
#, python-format
msgid ""
"_volume_attach_rollback: Volume %(id)s is missing restricted metadata to "
"recover the attaching state."
msgstr ""
"NV-C8F1D06 _volume_attach_rollback: ボリューム %(id)s "
"に、接続状態を復旧するための制限付きメタデータがありません。"

#: paxes_cinder/volume/manager.py:487
#, python-format
msgid ""
"_volume_attach_rollback: No attach operation  to rollback for volume "
"%(id)s"
msgstr ""
"NV-77AEEA1 _volume_attach_rollback: ボリューム %(id)s "
"について、ロールバックするための接続操作はありません"

#: paxes_cinder/volume/manager.py:493
#, python-format
msgid ""
"_volume_attach_rollback: Invalid connector %(conn)s in volume %(id)s "
"restrict metadata. Rollback without termination"
msgstr ""
"NV-4096184 _volume_attach_rollback: ボリューム %(id)s の制限メタデータに、無効なコネクター "
"%(conn)s があります。終了せずにロールバックします"

#: paxes_cinder/volume/manager.py:498
#, python-format
msgid "_volume_attach_rollback: Roll back attaching state for volume %(id)s."
msgstr "NV-1EB0444 _volume_attach_rollback: ボリューム %(id)s の接続状態をロールバックします。"

#: paxes_cinder/volume/manager.py:518
#, python-format
msgid ""
"_volume_attach_rollback: Finished. Volume %(id)s has rolled back to "
"available state."
msgstr ""
"NV-1E08B26 _volume_attach_rollback: 終了しました。ボリューム %(id)s "
"は使用可能状態にロールバックされました。"

#: paxes_cinder/volume/manager.py:600
#, python-format
msgid ""
"The volume detach didn't finish successfully before cinder service was "
"restarted. volume id: %(id)s"
msgstr "NV-333B81A cinder サービスが再開される前に、ボリュームの切り離しが正常に終了しませんでした。ボリューム ID: %(id)s"

#: paxes_cinder/volume/manager.py:633
msgid "Unable to initialize host, driver is uninitialized"
msgstr "NV-7F33CBC ホストを初期化できません。ドライバーは初期化されていません"

#: paxes_cinder/volume/manager.py:650
msgid "update default quota class..."
msgstr "NV-392B903 デフォルトの割り当て量クラスを更新します..."

#: paxes_cinder/volume/manager.py:652
msgid "Post init_host processing and update volume status."
msgstr "NV-6EC3032 init_host 後の処理およびボリューム状況の更新。"

#: paxes_cinder/volume/manager.py:656
#, python-format
msgid "Error happened during post init_host volume processing. Error: %s"
msgstr "NV-B263BC8 init_host 後のボリューム処理中にエラーが発生しました。エラー: %s"

#: paxes_cinder/volume/manager.py:660
#, python-format
msgid "Rollback volume still attaching during init_host: %d volumes"
msgstr "NV-BDEAFA8 init_host 中に、まだ接続されているボリュームをロールバックします: %d 個のボリューム"

#: paxes_cinder/volume/manager.py:665
#, python-format
msgid "Resume volume deletion during init_host: %d volumes"
msgstr "NV-6BC64FF init_host 中に、ボリュームの削除を再開します: %d 個のボリューム"

#: paxes_cinder/volume/manager.py:719
msgid "Caught Exception Refreshing Driver Status "
msgstr "ドライバー状況のリフレッシュ中に例外を受け取りました "

#: paxes_cinder/volume/manager.py:755
msgid "Caught Exception trying to update Storage Node in DB"
msgstr "NV-36093B5 DB のストレージ・ノードを更新しようとしているときに例外を受け取りました"

#: paxes_cinder/volume/manager.py:793
msgid "Unable to retrieve Default Volume Type"
msgstr "NV-544BC4C デフォルトのボリューム・タイプを取得できません"

#: paxes_cinder/volume/manager.py:850
#, python-format
msgid "volume %s: removing export"
msgstr "NV-BAF02FC ボリューム %s: エクスポートの削除中"

#: paxes_cinder/volume/manager.py:852
#, python-format
msgid "volume %s: deleting"
msgstr "NV-4F406DE ボリューム %s: 削除中"

#: paxes_cinder/volume/manager.py:855
#, python-format
msgid "volume %s: volume is busy"
msgstr "NV-3431BA6 ボリューム %s: ボリュームは使用中です"

#: paxes_cinder/volume/manager.py:858
#, python-format
msgid "Fail to remove_export or delete_volume: %sname"
msgstr "NV-E98201D remove_export または delete_volume の実行に失敗しました: %s 名"

#: paxes_cinder/volume/manager.py:862
#, python-format
msgid "Volume %s: deletion failed with exception "
msgstr "NV-137591B ボリューム %s: 例外が発生して削除できませんでした "

#: paxes_cinder/volume/manager.py:954
#, python-format
msgid ""
"failed checking whether                              volume %(vol_id)s "
"backs an image, metadata=%(mdata)s"
msgstr ""
"NV-BE4D3EE 次の検査に失敗しました:                              ボリューム %(vol_id)s "
"がイメージを返すかどうか。メタデータ=%(mdata)s"

#: paxes_cinder/volume/manager.py:991
#, python-format
msgid ""
"volume %(volid)s has unfinished attach transaction. Rolling back before "
"deleting the volume."
msgstr "NV-331CBBA ボリューム %(volid)s には未完了の接続トランザクションがあります。ボリュームを削除する前にロールバックしています。"

#: paxes_cinder/volume/manager.py:1035
#, python-format
msgid ""
"Quota exceeded for %(s_pid)s, tried to extend volume by %(s_size)sG, "
"(%(d_consumed)dG of %(d_quota)dG already consumed)"
msgstr ""
"NV-521C07E %(s_pid)s の割り当て量を超過しました。ボリュームの %(s_size)s G の拡張が試行されました "
"(%(d_consumed)d G/%(d_quota)d G が既に使用されました)"

#: paxes_cinder/volume/manager.py:1091
#, python-format
msgid ""
"The host %(hostid)s for boot volume %(volid)s  does not support extend "
"volume."
msgstr "NV-37CDE0F ブート・ボリューム %(volid)s のホスト %(hostid)s は、ボリュームの拡張をサポートしていません。"

#: paxes_cinder/volume/manager.py:1145
#, python-format
msgid "Start attach transaction for volume %(id)s."
msgstr "NV-1CBB13C ボリューム %(id)s の接続トランザクションを開始します。"

#: paxes_cinder/volume/manager.py:1175
#, python-format
msgid "Driver returned %s"
msgstr "NV-B695526 ドライバーが %s を返しました"

#: paxes_cinder/volume/manager.py:1208
#, python-format
msgid "Successfully attached the volume %(id)s. Clean up transaction."
msgstr "NV-F606087 ボリューム %(id)s は正常に接続されました。トランザクションをクリーンアップします。"

#: paxes_cinder/volume/drivers/paxes_san.py:162
#, python-format
msgid "Waiting %(seconds)d seconds before next attempt..."
msgstr "NV-0553DA5 次の試行まで %(seconds)d 秒待機中..."

#: paxes_cinder/volume/drivers/paxes_san.py:182
#, python-format
msgid "Error running SSH command: %s"
msgstr "NV-052C0AB SSH コマンドの実行中にエラーが発生しました: %s"

#: paxes_cinder/volume/drivers/emc/emc_common_product.py:35
msgid "Updating volume status"
msgstr "NV-A56DF8D ボリューム状況の更新中"

#: paxes_cinder/volume/drivers/emc/emc_smis_product.py:89
#: paxes_cinder/volume/drivers/svc/storwize_svc_driver_id.py:1374
msgid "protocol must be specified as '<in> iSCSI' or '<in> FC'"
msgstr "プロトコルとして '<in> iSCSI' または '<in> FC' を指定する必要があります"

#: paxes_cinder/volume/drivers/emc/emc_smis_product.py:123
msgid "Entering create_volume."
msgstr "NV-4C5AEEB create_volume を開始しています。"

#: paxes_cinder/volume/drivers/emc/emc_smis_product.py:127
#, python-format
msgid "Create Volume: %(volume)s  Size: %(size)lu"
msgstr "NV-403E8FC ボリュームの作成: %(volume)s、サイズ: %(size)lu"

#: paxes_cinder/volume/drivers/emc/emc_smis_product.py:157
#, python-format
msgid ""
"Unsupported element_type value %(element_type)s.  Specify a supported "
"element_type value and resubmit the request."
msgstr ""
"NV-AC11F99 サポートされない element_type 値 %(element_type)s です。サポートされる "
"element_type 値を指定し、要求を再実行依頼してください。"

#: paxes_cinder/volume/drivers/emc/emc_smis_product.py:164
#, python-format
msgid "Create Volume: %(volume)s  Storage type: %(storage_type)s"
msgstr "NV-4E4E2BB ボリュームの作成: %(volume)s、ストレージ・タイプ: %(storage_type)s"

#: paxes_cinder/volume/drivers/emc/emc_smis_product.py:171
#, python-format
msgid ""
"Create Volume: %(volume)s  Pool: %(pool)s,  Element Type: "
"%(element_type)s, Storage System: %(storage_system)s"
msgstr ""
"NV-723484A ボリュームの作成: %(volume)s、プール: %(pool)s、エレメント・タイプ: "
"%(element_type)s、ストレージ・システム: %(storage_system)s"

#: paxes_cinder/volume/drivers/emc/emc_smis_product.py:182
#, python-format
msgid ""
"Error Create Volume: %(volumename)s. Storage Configuration Service not "
"found for pool %(storage_type)s."
msgstr ""
"NV-0EFA73A ボリューム %(volumename)s の作成中にエラーが発生しました。プール %(storage_type)s "
"のストレージ構成サービスが見つかりません。"

#: paxes_cinder/volume/drivers/emc/emc_smis_product.py:190
#, python-format
msgid ""
"Create Volume: %(name)s  Method: CreateOrModifyElementFromStoragePool  "
"ConfigServicie: %(service)s  ElementName: %(name)s  InPool: %(pool)s  "
"ElementType: %(element_type)s  Size: %(size)lu"
msgstr ""
"NV-6E312B4 ボリュームの作成: %(name)s、メソッド: "
"CreateOrModifyElementFromStoragePool、ConfigServicie: "
"%(service)s、ElementName: %(name)s、InPool: %(pool)s、ElementType: "
"%(element_type)s、サイズ: %(size)lu"

#: paxes_cinder/volume/drivers/emc/emc_smis_product.py:206
#, python-format
msgid "Create Volume: %(volumename)s  Return code: %(rc)lu"
msgstr "NV-0214C49 ボリュームの作成: %(volumename)s、戻りコード: %(rc)lu"

#: paxes_cinder/volume/drivers/emc/emc_smis_product.py:213
#, python-format
msgid ""
"Error Create Volume: %(volumename)s.  Return code: %(rc)lu.  Error: "
"%(error)s"
msgstr "NV-227D3AC ボリュームの作成エラー: %(volumename)s。戻りコード: %(rc)lu。エラー: %(error)s"

#: paxes_cinder/volume/drivers/emc/emc_smis_product.py:220
#, python-format
msgid "Leaving create_volume: %(volumename)s  Return code: %(rc)lu"
msgstr "NV-C5C5CCC create_volume の設定中: %(volumename)s、戻りコード: %(rc)lu"

#: paxes_cinder/volume/drivers/emc/emc_smis_product.py:235
#: paxes_cinder/volume/drivers/emc/emc_smis_product.py:259
msgid "Could not establish ecom connection"
msgstr "NV-930992B ecom 接続を確立できませんでした"

#: paxes_cinder/volume/drivers/ssp/ssp.py:177
#, python-format
msgid "ssp:  no matching HMC was found in the DB for host: >%s<"
msgstr "NV-BFBE123 ssp: 一致する HMC がホスト >%s< の DB に見つかりませんでした。"

#: paxes_cinder/volume/drivers/ssp/ssp.py:248
#, python-format
msgid "ssp: during create default volume type, DB error: >%s<"
msgstr "NV-FA1BBE8 ssp: デフォルト・ボリューム・タイプ作成の間に、DB エラー >%s< がありました。"

#: paxes_cinder/volume/drivers/ssp/ssp.py:279
#, python-format
msgid ""
"ssp: during _create_lu for LU: (name: >%(name)s<, size: >%(size)s<, thin:"
" >%(thin)s<), ssp_udid: >%(ssp_udid)s< is not same as extra_spec "
"shared_storage_pool: >%(extra_spec_ssp_id)s<"
msgstr ""
"ssp: LU (名前: >%(name)s<、サイズ: >%(size)s<、シン: >%(thin)s<) の _create_lu "
"中、ssp_udid >%(ssp_udid)s< と extra_spec shared_storage_pool "
">%(extra_spec_ssp_id)s< が異なっています"

#: paxes_cinder/volume/drivers/ssp/ssp.py:299
#, python-format
msgid ""
"ssp: failed during _create_lu for LU: (name: >%(name)s<, size: "
">%(size)s<, thin: >%(thin)s<), message: >%(e)s<, k2xa: >%(k2xa)s<"
msgstr ""
"ssp: LU (名前: >%(name)s<、サイズ: >%(size)s<、シン: >%(thin)s<) の _create_lu "
"の間に障害がありました。メッセージ: >%(e)s<、k2xa: >%(k2xa)s<"

#: paxes_cinder/volume/drivers/ssp/ssp.py:329
#, python-format
msgid ""
"ssp: during _create_lu job for LU: (name: >%(name)s<, size: >%(size)s<, "
"thin: >%(thin)s<), ssp_udid: >%(ssp_udid)s< is not same as extra_spec "
"shared_storage_pool: >%(extra_spec_ssp_id)s<"
msgstr ""
"ssp: LU (名前: >%(name)s<、サイズ: >%(size)s<、シン: >%(thin)s<) の _create_lu "
"ジョブ中、ssp_udid >%(ssp_udid)s< と extra_spec shared_storage_pool "
">%(extra_spec_ssp_id)s< が異なっています"

#: paxes_cinder/volume/drivers/ssp/ssp.py:351
#, python-format
msgid ""
"ssp: failure during _create_lu, create parameters: name: >%(name)s<, "
"size: >%(size)s<, thin: >%(thin)s<, logicalunittype: "
">%(logicalunittype)s<, message: >%(e)s<, k2xa: >%(k2xa)s<"
msgstr ""
"ssp: _create_lu の間に障害がありました。作成パラメーター: 名前: >%(name)s<、サイズ: >%(size)s<、シン: "
">%(thin)s<、論理装置タイプ: >%(logicalunittype)s<、メッセージ: >%(e)s<、k2xa: >%(k2xa)s<"

#: paxes_cinder/volume/drivers/ssp/ssp.py:366
#, python-format
msgid ""
"ssp: failure during _create_lu job, expecting COMPLETED_OK, but for "
"job_id: >%(job_id)s< got status: >%(status)s< create parameters: name: "
">%(name)s<, size: >%(size)s<, thin: >%(thin)s<, logicalunittype: "
">%(logicalunittype)s<, k2xa: >%(k2xa)s<"
msgstr ""
"NV-76A9409 ssp: _create_lu ジョブの間に障害がありました。COMPLETED_OK を予期していましたが、job_id "
">%(job_id)s< について状況 >%(status)s< を受け取りました。作成パラメーター: 名前: >%(name)s<、サイズ: "
">%(size)s<、シン: >%(thin)s<、論理装置タイプ: >%(logicalunittype)s<、k2xa: >%(k2xa)s<"

#: paxes_cinder/volume/drivers/ssp/ssp.py:382
#, python-format
msgid ""
"ssp: create complete, job_id: >%(job_id)s<, name: >%(name)s<, size: "
">%(size)s<, thin: >%(thin)s<, logicalunittype: >%(logicalunittype)s<, "
"k2xa: >%(k2xa)s<"
msgstr ""
"NV-9FEEE64 ssp: 作成が完了しました。job_id: >%(job_id)s<、名前: >%(name)s<、サイズ: "
">%(size)s<、シン: >%(thin)s<、論理装置タイプ: >%(logicalunittype)s<、k2xa: >%(k2xa)s<"

#: paxes_cinder/volume/drivers/ssp/ssp.py:416
#, python-format
msgid ""
"ssp: failed during _delete_lu of LU w/ with unique_device_id: "
">%(lu_udid)s<,  message: >%(e)s<, k2xa: >%(k2xa)s<"
msgstr ""
"ssp: unique_device_id >%(lu_udid)s< の LU の _delete_lu の間に障害がありました。メッセージ: "
">%(e)s<、k2xa: >%(k2xa)s<"

#: paxes_cinder/volume/drivers/ssp/ssp.py:431
#, python-format
msgid ""
"ssp: during _clone_lu_by_name, couldnt find lu with src_lu_name: "
">%(src_lu_name)s<, tgt_lu_name: >%(tgt_lu_name)s<"
msgstr ""
"ssp: _clone_lu_by_name 中に、src_lu_name >%(src_lu_name)s<、tgt_lu_name "
">%(tgt_lu_name)s< の LU が見つかりませんでした"

#: paxes_cinder/volume/drivers/ssp/ssp.py:439
#, python-format
msgid ""
"ssp: during _clone_lu_by_name, found too many lus with src_lu_name: "
">%(src_lu_name)s<, tgt_lu_name: >%(tgt_lu_name)s<"
msgstr ""
"NV-8FDE368 ssp: _clone_lu_by_name 中に、見つかった src_lu_name "
">%(src_lu_name)s<、tgt_lu_name >%(tgt_lu_name)s< の LU が多すぎます"

#: paxes_cinder/volume/drivers/ssp/ssp.py:469
#, python-format
msgid ""
"ssp: failure during _clone_lu_bj, clone parameters: src_lu_udid: "
">%(src_lu_udid)s<, tgt_lu_name: >%(tgt_lu_name)s< tgt_lu_size: "
">%(tgt_lu_size)s< msg: >%(e)s<, k2xa: >%(k2xa)s<"
msgstr ""
"ssp: _clone_lu_bj の間に障害がありました。複製パラメーター: src_lu_udid: "
">%(src_lu_udid)s<、tgt_lu_name: >%(tgt_lu_name)s<、tgt_lu_size: "
">%(tgt_lu_size)s<、メッセージ: >%(e)s<、k2xa: >%(k2xa)s<"

#: paxes_cinder/volume/drivers/ssp/ssp.py:485
#: paxes_cinder/volume/drivers/ssp/ssp.py:547
#, python-format
msgid ""
"ssp: apparent failure during _clone_lu_bj, expecting COMPLETED_OK, but "
"for job_id: >%(job_id)s< got status: >%(status)s< clone parameters: "
"src_lu_udid: >%(src_lu_udid)s<, tgt_lu_name: >%(tgt_lu_name)s< "
"tgt_lu_size: >%(tgt_lu_size)s<, k2xa: >%(k2xa)s<"
msgstr ""
"NV-64234D9 ssp: _clone_lu_bj の間に明らかな障害がありました。COMPLETED_OK "
"を予期していましたが、job_id >%(job_id)s< について状況 >%(status)s< を受け取りました。複製パラメーター: "
"src_lu_udid: >%(src_lu_udid)s<、tgt_lu_name: "
">%(tgt_lu_name)s<、tgt_lu_size: >%(tgt_lu_size)s<、k2xa: >%(k2xa)s<"

#: paxes_cinder/volume/drivers/ssp/ssp.py:509
#, python-format
msgid ""
"ssp: failure during _clone_lu_bj, during create, clone parameters: "
"src_lu_udid: >%(src_lu_udid)s<, tgt_lu_name: >%(tgt_lu_name)s< "
"tgt_lu_size: >%(tgt_lu_size)s< message: >%(e)s<, k2xa: >%(k2xa)s<"
msgstr ""
"ssp: _clone_lu_bj の間、作成中に障害がありました。複製パラメーター: src_lu_udid: "
">%(src_lu_udid)s<、tgt_lu_name: >%(tgt_lu_name)s<、tgt_lu_size: "
">%(tgt_lu_size)s<、メッセージ: >%(e)s<、k2xa: >%(k2xa)s<"

#: paxes_cinder/volume/drivers/ssp/ssp.py:530
#, python-format
msgid ""
"ssp: failure during _clone_lu_bj, during clone, clone parameters: "
"src_lu_udid: >%(src_lu_udid)s<, tgt_lu_name: >%(tgt_lu_name)s< "
"tgt_lu_size: >%(tgt_lu_size)s< message: >%(e)s<, k2xa: >%(k2xa)s<"
msgstr ""
"ssp: _clone_lu_bj の間、複製中に障害がありました。複製パラメーター: src_lu_udid: "
">%(src_lu_udid)s<、tgt_lu_name: >%(tgt_lu_name)s<、tgt_lu_size: "
">%(tgt_lu_size)s<、メッセージ: >%(e)s<、k2xa: >%(k2xa)s<"

#: paxes_cinder/volume/drivers/ssp/ssp.py:576
#, python-format
msgid ""
"ssp: failure during _clone_lu_bp, clone parameters: src_lu_udid: "
">%(src_lu_udid)s<, tgt_lu_name: >%(tgt_lu_name)s< tgt_lu_size: "
">%(tgt_lu_size)s< message: >%(e)s<, k2xa: >%(k2xa)s<"
msgstr ""
"ssp: _clone_lu_bp の間に障害がありました。複製パラメーター: src_lu_udid: "
">%(src_lu_udid)s<、tgt_lu_name: >%(tgt_lu_name)s<、tgt_lu_size: "
">%(tgt_lu_size)s<、メッセージ: >%(e)s<、k2xa: >%(k2xa)s<"

#: paxes_cinder/volume/drivers/ssp/ssp.py:591
#, python-format
msgid ""
"ssp: apparent failure during _clone_lu_bp, expecting COMPLETED_OK, but "
"for job_id: >%(job_id)s< got status: >%(status)s< clone parameters: "
"src_lu_udid: >%(src_lu_udid)s<, tgt_lu_name: >%(tgt_lu_name)s< "
"tgt_lu_size: >%(tgt_lu_size)s<, k2xa: >%(k2xa)s<"
msgstr ""
"NV-21DAFDD ssp: _clone_lu_bp の間に明らかな障害がありました。COMPLETED_OK "
"を予期していましたが、job_id >%(job_id)s< について状況 >%(status)s< を受け取りました。複製パラメーター: "
"src_lu_udid: >%(src_lu_udid)s<、tgt_lu_name: "
">%(tgt_lu_name)s<、tgt_lu_size: >%(tgt_lu_size)s<、k2xa: >%(k2xa)s<"

#: paxes_cinder/volume/drivers/ssp/ssp.py:606
#, python-format
msgid ""
"ssp: clone complete, job_id: >%(job_id)s<, src_lu_udid: "
">%(src_lu_udid)s<, tgt_lu_name: >%(tgt_lu_name)s< tgt_lu_size: "
">%(tgt_lu_size)s<, k2xa: >%(k2xa)s<"
msgstr ""
"NV-330DF39 ssp: 複製が完了しました。job_id: >%(job_id)s<、src_lu_udid: "
">%(src_lu_udid)s<、tgt_lu_name: >%(tgt_lu_name)s<、tgt_lu_size: "
">%(tgt_lu_size)s<、k2xa: >%(k2xa)s<"

#: paxes_cinder/volume/drivers/ssp/ssp.py:625
msgid "ssp: driver not yet initialized"
msgstr "NV-767C35B ssp: ドライバーはまだ初期化されていません"

#: paxes_cinder/volume/drivers/ssp/ssp.py:634
#, python-format
msgid ""
"K2 GET SharedStoragePool time: >%(delta)f< is bigger or equal to "
"update_stats periodic interval: >%(periodic_interval)d<"
msgstr ""
"NV-BB646A1 K2 GET SharedStoragePool 時間 >%(delta)f< が、update_stats の定期的間隔 "
">%(periodic_interval)d< 以上になっています。"

#: paxes_cinder/volume/drivers/ssp/ssp.py:641
#, python-format
msgid ""
"ssp: during get_volume_stats, failed to refresh shared storage pool with "
"ssp_id: >%(self._ssp.id)s<, message: >%(e)s<, k2xa: >%(k2xa)s<"
msgstr ""
"ssp: get_volume_stats の間に、ssp_id >%(self._ssp.id)s< "
"の共有ストレージ・プールをリフレッシュできませんでした。メッセージ: >%(e)s<、k2xa: >%(k2xa)s<"

#: paxes_cinder/volume/drivers/ssp/ssp.py:680
#, python-format
msgid ""
"ssp: during %(duringwhatstage)s, while performing vios cluster check, "
"failed to refresh cluster id: >%(self._cluster.id)s<, k2xa: >%(k2xa)s<"
msgstr ""
"NV-AC40CF2 ssp: %(duringwhatstage)s の間、VIOS クラスター検査を実行しているときに、クラスター ID "
">%(self._cluster.id)s< をリフレッシュできませんでした。k2xa: >%(k2xa)s<"

#: paxes_cinder/volume/drivers/ssp/ssp.py:707
#, python-format
msgid ""
"ssp: during %(duringwhatstage)s, for vios id: >%(vios.id)s<, "
"OperatingSystemVersion: >%(os_version)s<"
msgstr ""
"ssp: %(duringwhatstage)s の間に、VIOS ID >%(vios.id)s< "
"についてオペレーティング・システム・バージョン >%(os_version)s< が見つかりました。"

#: paxes_cinder/volume/drivers/ssp/ssp.py:719
#, python-format
msgid ""
"ssp: during %(duringwhatstage)s, vios id: >%(vios.id)s<, running and "
"active"
msgstr "ssp: %(duringwhatstage)s 中、vios id >%(vios.id)s< は実行中でアクティブです"

#: paxes_cinder/volume/drivers/ssp/ssp.py:727
#, python-format
msgid ""
"ssp: during %(duringwhatstage)s, for cluster id: >%(self._cluster.id)s<, "
"vios state issue, vios id: >%(vios.id)s<: PartitionState: "
">%(vios.partition_state)s< ResourceMonitoringControlState: "
">%(vios.rmc_state)s<, k2xa: >%(k2xa)s<"
msgstr ""
"ssp: %(duringwhatstage)s の間に、クラスター ID >%(self._cluster.id)s< について VIOS "
"状態問題が見つかりました。VIOS ID: >%(vios.id)s<:、パーティション状態: "
">%(vios.partition_state)s<、リソース・モニター制御状態: >%(vios.rmc_state)s<、k2xa: "
">%(k2xa)s<"

#: paxes_cinder/volume/drivers/ssp/ssp.py:751
#, python-format
msgid ""
"ssp: during %(duringwhatstage)s, could not find restricted metadata for "
"volume id: >%(volume_id)s<"
msgstr ""
"ssp: %(duringwhatstage)s の間に、ボリューム ID %(volume_id)s< "
"の制限付きメタデータが見つかりませんでした。"

#: paxes_cinder/volume/drivers/ssp/ssp.py:767
#, python-format
msgid ""
"ssp: during %(duringwhatstage)s, failed to refresh shared storage pool "
"with ssp_id: >%(self._ssp.id)s<, message: >%(e)s<, k2xa: >%(k2xa)s<"
msgstr ""
"ssp: %(duringwhatstage)s の間に、ssp_id >%(self._ssp.id)s< "
"の共有ストレージ・プールをリフレッシュできませんでした。メッセージ: >%(e)s<、k2xa: >%(k2xa)s<"

#: paxes_cinder/volume/drivers/ssp/ssp.py:780
#, python-format
msgid ""
"ssp: during %(duringwhatstage)s, couldnt find lu for volume_id: "
">%(volume_id)s< with: unique_device_id: >%(lu_udid)s< and unit_name: "
">%(lu_name)s<"
msgstr ""
"ssp: %(duringwhatstage)s の間に、volume_id >%(volume_id)s< の LU "
"(unique_device_id: >%(lu_udid)s<、unit_name: >%(lu_name)s<) が見つかりませんでした。"

#: paxes_cinder/volume/drivers/ssp/ssp.py:791
#, python-format
msgid ""
"ssp: during %(duringwhatstage)s, found too many lus for volume_id: "
">%(volume_id)s< with: unique_device_id: >%(lu_udid)s< and unit_name: "
">%(lu_name)s<"
msgstr ""
"NV-338EFD0 ssp: %(duringwhatstage)s の間に、見つかった volume_id >%(volume_id)s< の"
" LU (unique_device_id: >%(lu_udid)s<、unit_name: >%(lu_name)s<) が多すぎます。"

#: paxes_cinder/volume/drivers/ssp/ssp.py:805
#: paxes_cinder/volume/drivers/svc/storwize_svc_driver_id.py:342
msgid "enter: do_setup"
msgstr "NV-9097266 入力: do_setup"

#: paxes_cinder/volume/drivers/ssp/ssp.py:825
msgid "ssp: failure during do_setup, cant find hmc."
msgstr "NV-AE8B2E2 ssp: do_setup 中の失敗。hmc が見つかりません。"

#: paxes_cinder/volume/drivers/ssp/ssp.py:853
#, python-format
msgid ""
"ssp: during do_setup, failed to obtain k2client, k2_url: >%(k2_url)s<, "
"k2_username: >%(k2_username)s<"
msgstr ""
"ssp: do_setup 中、k2client を取得できませんでした。k2_url: >%(k2_url)s<、k2_username: "
">%(k2_username)s<"

#: paxes_cinder/volume/drivers/ssp/ssp.py:866
#, python-format
msgid ""
"ssp: during do_setup, using hmc_uuid: >%(hmc_uuid)s<, failed to retrieve "
"managementconsole, k2xa: >%(k2xa)s<"
msgstr ""
"ssp: do_setup の間に、hmc_uuid >%(hmc_uuid)s< を使用して管理コンソールを取得できませんでした。k2xa: "
">%(k2xa)s<"

#: paxes_cinder/volume/drivers/ssp/ssp.py:875
#, python-format
msgid "ssp: during do_setup, hmc version: >%s<"
msgstr "NV-3F31730 ssp: do_setup 中の hmc バージョン: >%s<"

#: paxes_cinder/volume/drivers/ssp/ssp.py:885
#, python-format
msgid ""
"ssp: during do_setup, using k2_url: >%(k2_url)s<, failed to retrieve "
"cluster, cluster_id: >%(cluster_id)s<, k2xa: >%(k2xa)s<"
msgstr ""
"ssp: do_setup の間に、k2_url >%(k2_url)s< を使用してクラスターを取得できませんでした。cluster_id: "
">%(cluster_id)s<、k2xa: >%(k2xa)s<"

#: paxes_cinder/volume/drivers/ssp/ssp.py:904
#, python-format
msgid ""
"ssp: during do_setup, using k2_url: >%(k2_url)s< and cluster_id: "
">%(cluster_id)s< failed to retrieve shared storage pool with ssp_ip: "
">%(ssp_id)s<, k2xa: >%(k2xa)s<"
msgstr ""
"ssp: do_setup の間に、k2_url >%(k2_url)s< および cluster_id >%(cluster_id)s< "
"を使用して、ssp_ip >%(ssp_id)s< の共有ストレージ・プールを取得できませんでした。k2xa: >%(k2xa)s<"

#: paxes_cinder/volume/drivers/ssp/ssp.py:923
#, python-format
msgid "ssp: during do_setup, creating default volume type: >%s<"
msgstr "NV-379E7B0 ssp: do_setup 中、デフォルトのボリューム・タイプ >%s< を作成しています"

#: paxes_cinder/volume/drivers/ssp/ssp.py:928
#: paxes_cinder/volume/drivers/svc/storwize_svc_driver_id.py:487
msgid "leave: do_setup"
msgstr "NV-F492AE8 設定: do_setup"

#: paxes_cinder/volume/drivers/ssp/ssp.py:931
#: paxes_cinder/volume/drivers/svc/storwize_svc_driver_id.py:580
msgid "leave: check_for_setup_error"
msgstr "NV-1C79D46 設定: check_for_setup_error"

#: paxes_cinder/volume/drivers/ssp/ssp.py:981
#: paxes_cinder/volume/drivers/ssp/ssp.py:1009
#: paxes_cinder/volume/drivers/ssp/ssp.py:1050
#: paxes_cinder/volume/drivers/ssp/ssp.py:1149
#: paxes_cinder/volume/drivers/ssp/ssp_product.py:48
#: paxes_cinder/volume/drivers/ssp/ssp_product.py:73
#: paxes_cinder/volume/drivers/ssp/ssp_product.py:145
#, python-format
msgid "ssp: exception: >%s<"
msgstr "NV-31FED69 ssp: 例外: >%s<"

#: paxes_cinder/volume/drivers/ssp/ssp.py:982
msgid "ssp: failed during create_volume"
msgstr "NV-E4EE3DB ssp: create_volume 中に失敗しました"

#: paxes_cinder/volume/drivers/ssp/ssp.py:1010
#, python-format
msgid ""
"ssp: failed during delete_volume, lu_udid: >%(lu_udid)s< lu_name: "
">%(lu_name)s< volume id: >%(volume_id)s<, k2xa: >%(k2xa)s<"
msgstr ""
"NV-41060EC ssp: delete_volume の間に障害がありました。lu_udid: >%(lu_udid)s<、lu_name:"
" >%(lu_name)s<、ボリューム ID: >%(volume_id)s<、k2xa: >%(k2xa)s<"

#: paxes_cinder/volume/drivers/ssp/ssp.py:1029
#, python-format
msgid "ssp: during create_snapshot, cant find volume_id: >%s<"
msgstr "NV-FDA9D85 ssp: create_snapshot の間に、volume_id >%s< が見つかりません。"

#: paxes_cinder/volume/drivers/ssp/ssp.py:1051
#, python-format
msgid ""
"ssp: failure during create_snapshot: lu_udid: >%(src_lu_udid)s< lu_name: "
">%(src_lu_name)s< volume id: >%(source_vol_id)s<, k2xa: >%(k2xa)s<"
msgstr ""
"NV-ACF24A1 ssp: create_snapshot の間に障害がありました。lu_udid: "
">%(src_lu_udid)s<、lu_name: >%(src_lu_name)s<、ボリューム ID: "
">%(source_vol_id)s<、k2xa: >%(k2xa)s<"

#: paxes_cinder/volume/drivers/ssp/ssp.py:1070
#, python-format
msgid "ssp: during delete_snapshot, couldnt find lu with unit_name: >%s<"
msgstr "NV-FCB5EA8 ssp: delete_snapshot の間に、unit_name >%s< の LU が見つかりませんでした。"

#: paxes_cinder/volume/drivers/ssp/ssp.py:1077
#, python-format
msgid "ssp: during delete_snapshot, found too many lus with unit_name: >%s<"
msgstr "NV-66B083E ssp: delete_snapshot の間に、見つかった unit_name >%s< の LU が多すぎます。"

#: paxes_cinder/volume/drivers/ssp/ssp.py:1105
#, python-format
msgid ""
"ssp: error during create_volume_from_snapshot: snapshot with name: "
">%(snapshot_name)s<, k2xa: >%(k2xa)s<"
msgstr ""
"NV-F6CFF00 ssp: create_volume_from_snapshot の間にエラーがありました。名前: "
">%(snapshot_name)s<、k2xa: >%(k2xa)s<"

#: paxes_cinder/volume/drivers/ssp/ssp.py:1150
#, python-format
msgid ""
"ssp:  error during create_cloned_volume: src_lu_udid: >%(src_lu_udid)s< "
"src_lu_name: >%(src_lu_name)s< volume id: >%(src_volume_id)s<, k2xa: "
">%(k2xa)s<"
msgstr ""
"NV-24854A9 ssp: create_cloned_volume の間にエラーがありました。src_lu_udid: "
">%(src_lu_udid)s<、src_lu_name: >%(src_lu_name)s<、ボリューム ID: "
">%(src_volume_id)s<、k2xa: >%(k2xa)s<"

#: paxes_cinder/volume/drivers/ssp/ssp.py:1211
#, python-format
msgid "stats = %(stats)s"
msgstr "NV-898A2AA 状況 = %(stats)s"

#: paxes_cinder/volume/drivers/ssp/ssp_product.py:49
#, python-format
msgid ""
"ssp: while discovering mapped LUs, failed to refresh cluster with "
"cluster_id: >%(self._cluster.id)s<, k2xa: >%(k2xa)s<"
msgstr ""
"NV-347194B ssp: マップされた LU を検出している間に、cluster_id >%(self._cluster.id)s< "
"のクラスターをリフレッシュできませんでした。k2xa: >%(k2xa)s<"

#: paxes_cinder/volume/drivers/ssp/ssp_product.py:59
#, python-format
msgid "Node >%s< has no virtual_io_server. Skipping."
msgstr "NV-C3FDDFD ノード >%s< には virtual_io_server がありません。スキップします。"

#: paxes_cinder/volume/drivers/ssp/ssp_product.py:74
#, python-format
msgid ""
"ssp: while discovering mapped LUs, in cluster with cluster_id: "
">%(self._cluster.id)s< failed to retrieve vios with managedsystem_id: "
">%(ms_id)s< and virtualioserver_id: >%(vios_id)s<, k2xa: >%(k2xa)s<"
msgstr ""
"NV-F12DD40 ssp: マップされた LU を検出している間に、cluster_id >%(self._cluster.id)s< "
"のクラスターで、managedsystem_id >%(ms_id)s< および virtualioserver_id >%(vios_id)s<"
" の VIOS を取得できませんでした。k2xa: >%(k2xa)s<"

#: paxes_cinder/volume/drivers/ssp/ssp_product.py:115
msgid ""
"No volume statistics available, either driver has not been initialized or"
" there is a problem w/ the driver, check cinder logs."
msgstr ""
"NV-A8A5D70 ボリューム統計がありません。ドライバーが初期化されていないか、またはドライバーに問題があります。cinder "
"ログを調べてください。"

#: paxes_cinder/volume/drivers/ssp/ssp_product.py:146
#, python-format
msgid ""
"ssp: while discovering volumes, failed to refresh shared storage pool "
"with ssp_id: >%(self._ssp.id)s<, k2xa: >%(k2xa)s<"
msgstr ""
"NV-7BF09DB ssp: ボリュームを検出している間に、ssp_id >%(self._ssp.id)s< "
"の共有ストレージ・プールをリフレッシュできませんでした。k2xa: >%(k2xa)s<"

#: paxes_cinder/volume/drivers/ssp/ssp_product.py:173
msgid ""
"This volume is not a candidate for management because it is already "
"attached to a virtual machine.  To manage this volume with PowerVC, you "
"must bring the virtual machine under management.  Select to manage the "
"virtual machine that has the volume attached.  The attached volume will "
"be automatically included for management."
msgstr ""
"このボリュームは既に仮想マシンに接続されているため、管理の候補ではありません。このボリュームを PowerVC "
"で管理するには、仮想マシンを管理下におく必要があります。ボリュームが接続されている仮想マシンを管理するよう選択してください。接続されているボリュームは自動的に、管理対象に組み込まれます。"

#: paxes_cinder/volume/drivers/ssp/ssp_product.py:184
#, python-format
msgid ""
"ssp: during Logical Unit discovery, ssp_id: >%(ssp_id)s<, "
"lu_unique_device_id: >%(lu_unique_device_id)s<, lu_unit_name: "
">%(lu_unit_name)s<, volume is in use and not available for management, "
"k2xa: >%(k2xa)s<"
msgstr ""
"ssp: 論理装置ディスカバリー (ssp_id: >%(ssp_id)s<、lu_unique_device_id: "
">%(lu_unique_device_id)s<、lu_unit_name: >%(lu_unit_name)s<) "
"の間、ボリュームは使用されていて、管理可能ではありません。k2xa: >%(k2xa)s<"

#: paxes_cinder/volume/drivers/ssp/ssp_product.py:200
msgid ""
"Because it is of type VirtualIO_Image, this volume is not a candidate for"
" management. Perhaps, while deleting a PowerVC image, someone chose not "
"to delete the backing storage? If you wish to work with the underlying "
"Shared Storage Pool Logical Unit please use the HMC or VIOS commands."
msgstr ""
"このボリュームはタイプ VirtualIO_Image であるため、管理の候補ではありません。PowerVC "
"イメージを削除するときに、いずれかのユーザーが補助ストレージを削除しないよう選択したと考えられます。基礎となる共有ストレージ・プール論理装置を操作したい場合、HMC"
" または VIOS コマンドを使用してください。"

#: paxes_cinder/volume/drivers/ssp/ssp_product.py:210
#, python-format
msgid ""
"ssp: during Logical Unit discovery, ssp_id: >%(ssp_id)s<, "
"lu_unique_device_id: >%(lu_unique_device_id)s<, lu_unit_name: "
">%(lu_unit_name)s<, volume is of type VirtualIO_Image and not available  "
"for management, k2xa: >%(k2xa)s<"
msgstr ""
"ssp: 論理装置ディスカバリー (ssp_id: >%(ssp_id)s<、lu_unique_device_id: "
">%(lu_unique_device_id)s<、lu_unit_name: >%(lu_unit_name)s<) の間、ボリュームはタイプ "
"VirtualIO_Image であり、管理可能ではありません。k2xa: >%(k2xa)s<"

#: paxes_cinder/volume/drivers/svc/storwize_svc_driver_id.py:240
#, python-format
msgid "WWPN on node %(node)s: %(wwpn)s"
msgstr "NV-D154765 ノード %(node)s 上の WWPN: %(wwpn)s"

#: paxes_cinder/volume/drivers/svc/storwize_svc_driver_id.py:299
#, python-format
msgid "Required keys %(required)s not found in vdisk dictionary %(dictionary)r"
msgstr "必須のキー %(required)s が仮想ディスク・ディクショナリー %(dictionary)r に見つかりません"

#: paxes_cinder/volume/drivers/svc/storwize_svc_driver_id.py:349
msgid "do_setup: Could not get system name"
msgstr "NV-5732B20 do_setup: システム名を取得できませんでした"

#: paxes_cinder/volume/drivers/svc/storwize_svc_driver_id.py:361
#, python-format
msgid "do_setup: Pool %s does not exist"
msgstr "NV-1B3A18D do_setup: プール %s は存在しません"

#: paxes_cinder/volume/drivers/svc/storwize_svc_driver_id.py:412
#, python-format
msgid ""
"Expected integers for node_count and vdisk_count, svcinfo lsiogrp "
"returned: %(node)s and %(vdisk)s"
msgstr ""
"NV-D7E5D72 node_count と vdisk_count には整数が予期されていましたが、svcinfo lsiogrp "
"が返されました: %(node)s と %(vdisk)s"

#: paxes_cinder/volume/drivers/svc/storwize_svc_driver_id.py:475
msgid "do_setup: No configured nodes"
msgstr "do_setup: 構成されたノードがありません"

#: paxes_cinder/volume/drivers/svc/storwize_svc_driver_id.py:484
#, python-format
msgid "Creating default volume type '%s'"
msgstr "NV-5FF13AA デフォルトのボリューム・タイプ '%s' の作成中"

#: paxes_cinder/volume/drivers/svc/storwize_svc_driver_id.py:541
msgid "enter: check_for_setup_error"
msgstr "入力: check_for_setup_error"

#: paxes_cinder/volume/drivers/svc/storwize_svc_driver_id.py:545
msgid "Unable to determine system name"
msgstr "NV-82D9304 システム名を判別できません"

#: paxes_cinder/volume/drivers/svc/storwize_svc_driver_id.py:548
msgid "Unable to determine system id"
msgstr "NV-3C12EE7 システム ID を判別できません"

#: paxes_cinder/volume/drivers/svc/storwize_svc_driver_id.py:551
msgid "Unable to determine pool extent size"
msgstr "NV-D455E3E プール・エクステント・サイズを判別できません"

#: paxes_cinder/volume/drivers/svc/storwize_svc_driver_id.py:558
#, python-format
msgid "%s is not set"
msgstr "NV-6919A40 %s が設定されていません"

#: paxes_cinder/volume/drivers/svc/storwize_svc_driver_id.py:564
msgid ""
"Password or SSH private key is required for authentication: set either "
"san_password or san_private_key option"
msgstr ""
"NV-6FE00A0 認証にはパスワードまたは SSH 秘密鍵が必要です: san_password または san_private_key "
"オプションを設定してください"

#: paxes_cinder/volume/drivers/svc/storwize_svc_driver_id.py:572
#, python-format
msgid ""
"Illegal value %d specified for storwize_svc_flashcopy_timeout: valid "
"values are between 0 and 600"
msgstr ""
"NV-F2E38D9 storwize_svc_flashcopy_timeout に指定された値 %d が正しくありません: 有効な値は 0 "
"から 600 です"

#: paxes_cinder/volume/drivers/svc/storwize_svc_driver_id.py:594
#, python-format
msgid "ensure_export: Volume %(volume_id)s does not reference a vdisk"
msgstr "NV-EF2904A ensure_export: ボリューム %(volume_id)s は仮想ディスクを参照していません"

#: paxes_cinder/volume/drivers/svc/storwize_svc_driver_id.py:601
#, python-format
msgid ""
"ensure_export: Volume %(volume_id)s references vdisk %(vdisk)s, which was"
" not found on storage"
msgstr ""
"NV-C3410C4 ensure_export: ボリューム %(volume_id)s は、ストレージに見つからなかった仮想ディスク "
"%(vdisk)s を参照しています"

#: paxes_cinder/volume/drivers/svc/storwize_svc_driver_id.py:627
#, python-format
msgid "enter: _get_chap_secret_for_host: host name %s"
msgstr "入力: _get_chap_secret_for_host: ホスト名 %s"

#: paxes_cinder/volume/drivers/svc/storwize_svc_driver_id.py:663
#, python-format
msgid ""
"leave: _get_chap_secret_for_host: host name %(host_name)s with secret "
"%(chap_secret)s"
msgstr "設定: _get_chap_secret_for_host: ホスト名 %(host_name)s と秘密 %(chap_secret)s"

#: paxes_cinder/volume/drivers/svc/storwize_svc_driver_id.py:686
msgid "_create_host: Cannot clean host name. Host name is not unicode or string"
msgstr "NV-ED84213 _create_host: ホスト名をクリーンアップできません。ホスト名が Unicode でもストリングでもありません"

#: paxes_cinder/volume/drivers/svc/storwize_svc_driver_id.py:837
#, python-format
msgid "enter: _get_host_from_connector: prefix %s"
msgstr "入力: _get_host_from_connector: プレフィックス %s"

#: paxes_cinder/volume/drivers/svc/storwize_svc_driver_id.py:865
#, python-format
msgid ""
"Continue to fall back processing after initial failure to make a host on "
"the SAN controller: %s"
msgstr "NV-41DBBAB 初期障害の後で処理のフォールバックを続行し、ホストを SAN コントローラー %s 上に作成します。"

#: paxes_cinder/volume/drivers/svc/storwize_svc_driver_id.py:909
#, python-format
msgid "leave: _get_host_from_connector: host %s"
msgstr "設定: _get_host_from_connector: ホスト %s"

#: paxes_cinder/volume/drivers/svc/storwize_svc_driver_id.py:921
#, python-format
msgid "enter: _create_host: host %s"
msgstr "入力: _create_host: ホスト %s"

#: paxes_cinder/volume/drivers/svc/storwize_svc_driver_id.py:936
msgid "_create_host: No connector ports"
msgstr "_create_host: コネクター・ポートがありません"

#: paxes_cinder/volume/drivers/svc/storwize_svc_driver_id.py:969
#, python-format
msgid "leave: _create_host: host %(host)s - %(host_name)s"
msgstr "設定: _create_host: ホスト %(host)s - %(host_name)s"

#: paxes_cinder/volume/drivers/svc/storwize_svc_driver_id.py:992
#, python-format
msgid "enter: _map_vol_to_host: vdisk %(vdisk_id)s to host %(host_name)s"
msgstr "入力: _map_vol_to_host: 仮想ディスク %(vdisk_id)s からホスト %(host_name)s へ"

#: paxes_cinder/volume/drivers/svc/storwize_svc_driver_id.py:1022
msgid ""
"storwize_svc_multihostmap_enabled is set to False, Not allow multi host "
"mapping"
msgstr ""
"NV-ABB7D85 storwize_svc_multihostmap_enabled は False "
"に設定されています。マルチホストのマッピングは許可されません"

#: paxes_cinder/volume/drivers/svc/storwize_svc_driver_id.py:1034
#, python-format
msgid "vdisk %s mapping to multi host"
msgstr "NV-45393AC 仮想ディスク %s がマルチホストにマッピングされています"

#: paxes_cinder/volume/drivers/svc/storwize_svc_driver_id.py:1040
#, python-format
msgid ""
"leave: _map_vol_to_host: LUN %(result_lun)s, vdisk %(vdisk_id)s, host "
"%(host_name)s"
msgstr ""
"設定: _map_vol_to_host: LUN %(result_lun)s、仮想ディスク %(vdisk_id)s、ホスト "
"%(host_name)s"

#: paxes_cinder/volume/drivers/svc/storwize_svc_driver_id.py:1050
#, python-format
msgid "enter: _delete_host: host %s "
msgstr "入力: _delete_host: ホスト %s "

#: paxes_cinder/volume/drivers/svc/storwize_svc_driver_id.py:1058
#, python-format
msgid "leave: _delete_host: host %s "
msgstr "設定: _delete_host: ホスト %s "

#: paxes_cinder/volume/drivers/svc/storwize_svc_driver_id.py:1084
#, python-format
msgid ""
"The connector does not contain the required information: %(connector)s, "
"protocols %(protos)s"
msgstr "NV-6A00D73 コネクターに、必要な情報が含まれていません: %(connector)s、プロトコル %(protos)s"

#: paxes_cinder/volume/drivers/svc/storwize_svc_driver_id.py:1105
#, python-format
msgid "Enter: initialize_connection: %s"
msgstr "NV-4DB79BA 入力: initialize_connection: %s"

#: paxes_cinder/volume/drivers/svc/storwize_svc_driver_id.py:1128
#, python-format
msgid "Did not find expected column name in lsvdisk: %s"
msgstr "NV-5EFF8EA 予期された列名が lsvdisk で見つかりませんでした: %s"

#: paxes_cinder/volume/drivers/svc/storwize_svc_driver_id.py:1130
#, python-format
msgid "initialize_connection: Missing volume attribute for vdisk %s"
msgstr "NV-4FE8A8D initialize_connection: 仮想ディスク %s のボリューム属性がありません"

#: paxes_cinder/volume/drivers/svc/storwize_svc_driver_id.py:1142
msgid "_create_host failed to return the host name."
msgstr "_create_host がホスト名を返すことができませんでした。"

#: paxes_cinder/volume/drivers/svc/storwize_svc_driver_id.py:1164
#, python-format
msgid ""
"initialize_connection: No node found in I/O group %(gid)s for vdisk "
"%(vdisk_id)s"
msgstr ""
"NV-8182517 initialize_connection: 仮想ディスク %(vdisk_id)s の入出力グループ %(gid)s "
"でノードが見つかりません"

#: paxes_cinder/volume/drivers/svc/storwize_svc_driver_id.py:1173
#, python-format
msgid "initialize_connection: Did not find a preferred node for vdisk %s"
msgstr "NV-1DB16EC initialize_connection: 仮想ディスク %s の優先ノードが見つかりませんでした"

#: paxes_cinder/volume/drivers/svc/storwize_svc_driver_id.py:1195
msgid ""
"Could not get FC connection information for the host-volume connection. "
"Is the host configured properly for FC connections?"
msgstr "NV-D8556EE ホスト-ボリューム間の接続に関する FC 接続情報を取得できませんでした。ホストは FC 接続用に正しく構成されていますか?"

#: paxes_cinder/volume/drivers/svc/storwize_svc_driver_id.py:1210
#, python-format
msgid ""
"initialize_connection: Failed to collect return properties for volume "
"%(vol)s and connector %(conn)s.\n"
msgstr ""
"NV-0A9D0F9 initialize_connection: ボリューム %(vol)s とコネクター %(conn)s "
"の戻りプロパティーを収集できませんでした。\n"

#: paxes_cinder/volume/drivers/svc/storwize_svc_driver_id.py:1215
#, python-format
msgid ""
"leave: initialize_connection:\n"
" volume: %(vol)s\n"
" connector %(conn)s\n"
" properties: %(prop)s"
msgstr ""
"設定: initialize_connection:\n"
"ボリューム: %(vol)s\n"
"コネクター %(conn)s\n"
"プロパティー: %(prop)s"

#: paxes_cinder/volume/drivers/svc/storwize_svc_driver_id.py:1233
#, python-format
msgid "enter: terminate_connection: volume %(vol)s with connector %(conn)s"
msgstr "入力: terminate_connection: ボリューム %(vol)s とコネクター %(conn)s"

#: paxes_cinder/volume/drivers/svc/storwize_svc_driver_id.py:1246
#, python-format
msgid ""
"terminate_connection: vdisk mismatch: %(err)s. Performing no operation on"
" the storage controller"
msgstr ""
"NV-78DEE4C terminate_connection: 仮想ディスクの不一致: "
"%(err)s。ストレージ・コントローラーではいずれの操作も実行されていません"

#: paxes_cinder/volume/drivers/svc/storwize_svc_driver_id.py:1252
#, python-format
msgid ""
"terminate_connection: vdisk deleted: %(err)s. Performing no operation on "
"the storage controller"
msgstr ""
"NV-0E7CDF3 terminate_connection: 仮想ディスクは削除されました: "
"%(err)s。ストレージ・コントローラーではいずれの操作も実行されていません"

#: paxes_cinder/volume/drivers/svc/storwize_svc_driver_id.py:1265
#, python-format
msgid "Detach volume: failed to lookup host name for vdisk ID: %(vdisk)s"
msgstr "NV-5D2DC5C ボリュームの切り離し: vdisk ID %(vdisk)s のホスト名を検索できませんでした。"

#: paxes_cinder/volume/drivers/svc/storwize_svc_driver_id.py:1291
#, python-format
msgid ""
"There was an error when attempting to remove the host disk mappings for "
"volume ID %(vol)s and vdsik ID %(vdisk)s: %(err)s"
msgstr ""
"NV-07BAF93 ボリューム ID %(vol)s および vdisk ID %(vdisk)s "
"のホスト・ディスク・マッピングを削除しようと試みているときに、エラーがありました: %(err)s"

#: paxes_cinder/volume/drivers/svc/storwize_svc_driver_id.py:1303
#, python-format
msgid ""
"terminate_connection: No mapping of vdisk %(vdisk_id)s to host "
"%(host_name)s found"
msgstr ""
"NV-0CD2F25 terminate_connection: 仮想ディスク %(vdisk_id)s からホスト %(host_name)s "
"へのマッピングが見つかりません"

#: paxes_cinder/volume/drivers/svc/storwize_svc_driver_id.py:1314
#, python-format
msgid "leave: terminate_connection: volume %(vol)s with connector %(conn)s"
msgstr "設定: terminate_connection: ボリューム %(vol)s とコネクター %(conn)s"

#: paxes_cinder/volume/drivers/svc/storwize_svc_driver_id.py:1414
#: paxes_cinder/volume/drivers/svc/storwize_svc_product.py:118
#, python-format
msgid "enter: _create_vdisk: candidate names %s "
msgstr "NV-2D6FE98 入力: _create_vdisk: 候補名 %s "

#: paxes_cinder/volume/drivers/svc/storwize_svc_driver_id.py:1470
#: paxes_cinder/volume/drivers/svc/storwize_svc_product.py:218
#, python-format
msgid ""
"_create_vdisk %(name)s - did not find success message in CLI output.\n"
" stdout: %(out)s\n"
" stderr: %(err)s"
msgstr ""
"_create_vdisk %(name)s - CLI 出力に正常終了メッセージが見つかりませんでした。\n"
" stdout: %(out)s\n"
" stderr: %(err)s"

#: paxes_cinder/volume/drivers/svc/storwize_svc_driver_id.py:1477
#: paxes_cinder/volume/drivers/svc/storwize_svc_product.py:225
#, python-format
msgid "leave: _create_vdisk: volume %(name)s ID %(id)s "
msgstr "NV-3A4E903 設定: _create_vdisk: ボリューム %(name)s ID %(id)s "

#: paxes_cinder/volume/drivers/svc/storwize_svc_driver_id.py:1499
#: paxes_cinder/volume/drivers/svc/storwize_svc_driver_id.py:1513
#, python-format
msgid ""
"create FC mapping from %(source)s to %(target)s - did not find success "
"message in CLI output.\n"
" stdout: %(out)s\n"
" stderr: %(err)s\n"
msgstr ""
"%(source)s から %(target)s への FC マッピング作成 - CLI 出力に正常終了メッセージが\n"
"見つかりませんでした。\n"
" stdout: %(out)s\n"
" stderr: %(err)s\n"

#: paxes_cinder/volume/drivers/svc/storwize_svc_driver_id.py:1525
#: paxes_cinder/volume/drivers/svc/storwize_svc_driver_id.py:1535
#, python-format
msgid ""
"create FC mapping from %(source)s to %(target)s - did not find mapping id"
" in CLI output.\n"
" stdout: %(out)s\n"
" stderr: %(err)s\n"
msgstr ""
"%(source)s から %(target)s への FC マッピング作成 - CLI 出力にマッピング ID が\n"
"見つかりませんでした。\n"
" stdout: %(out)s\n"
" stderr: %(err)s\n"

#: paxes_cinder/volume/drivers/svc/storwize_svc_driver_id.py:1550
#, python-format
msgid ""
"_prepare_fc_map: Failed to prepare FlashCopy from %(source)s to "
"%(target)s.\n"
"stdout: %(out)s\n"
" stderr: %(err)s"
msgstr ""
"NV-AD077CD _prepare_fc_map: %(source)s から %(target)s への FlashCopy "
"を準備できませんでした。\n"
" stdout: %(out)s\n"
" stderr: %(err)s"

#: paxes_cinder/volume/drivers/svc/storwize_svc_driver_id.py:1578
#, python-format
msgid ""
"Unexecpted mapping status %(status)s for mapping %(id)s. Attributes: "
"%(attr)s"
msgstr "マッピング %(id)s のマッピング状況 %(status)s は予期されていません。属性: %(attr)s"

#: paxes_cinder/volume/drivers/svc/storwize_svc_driver_id.py:1590
#, python-format
msgid ""
"Mapping %(id)s prepare failed to complete within the allotted %(to)d "
"seconds timeout. Terminating."
msgstr "NV-46B21B5 マッピング %(id)s の準備を、割り当てられたタイムアウトの %(to)d 秒以内に完了できませんでした。終了します。"

#: paxes_cinder/volume/drivers/svc/storwize_svc_driver_id.py:1595
#, python-format
msgid ""
"_prepare_fc_map: Failed to start FlashCopy from %(source)s to %(target)s "
"with exception %(ex)s"
msgstr ""
"NV-B48FD34 _prepare_fc_map: 例外 %(ex)s が発生したため、%(source)s から %(target)s への"
" FlashCopy を開始できませんでした"

#: paxes_cinder/volume/drivers/svc/storwize_svc_driver_id.py:1602
#, python-format
msgid "_prepare_fc_map: %s"
msgstr "NV-956CB6C _prepare_fc_map: %s"

#: paxes_cinder/volume/drivers/svc/storwize_svc_driver_id.py:1609
#, python-format
msgid ""
"_start_fc_map: Failed to start FlashCopy from %(source)s to %(target)s.\n"
"stdout: %(out)s\n"
" stderr: %(err)s"
msgstr ""
"NV-FCBE987 _start_fc_map: %(source)s から %(target)s への FlashCopy "
"を開始できませんでした。\n"
" stdout: %(out)s\n"
" stderr: %(err)s"

#: paxes_cinder/volume/drivers/svc/storwize_svc_driver_id.py:1620
#, python-format
msgid ""
"enter: _run_flashcopy: execute FlashCopy from source %(source)s to target"
" %(target)s"
msgstr "入力: _run_flashcopy: ソース %(source)s からターゲット %(target)s への FlashCopy を実行"

#: paxes_cinder/volume/drivers/svc/storwize_svc_driver_id.py:1633
#, python-format
msgid "leave: _run_flashcopy: FlashCopy started from %(source)s to %(target)s"
msgstr "設定: _run_flashcopy: %(source)s から %(target)s への FlashCopy が開始されました"

#: paxes_cinder/volume/drivers/svc/storwize_svc_driver_id.py:1642
#, python-format
msgid ""
"enter: _create_copy: snapshot with possible names %(names)s from vdisk "
"%(src_vdisk)s"
msgstr "入力: _create_copy: 仮想ディスク %(src_vdisk)s からのスナップショット (使用可能な名前 %(names)s)"

#: paxes_cinder/volume/drivers/svc/storwize_svc_driver_id.py:1650
#, python-format
msgid "_create_copy: Source vdisk %s does not exist"
msgstr "NV-8A48F71 _create_copy: ソース仮想ディスク %s は存在しません"

#: paxes_cinder/volume/drivers/svc/storwize_svc_driver_id.py:1662
#, python-format
msgid ""
"_create_copy: cannot get source vdisk %(src)s capacity from vdisk "
"attributes %(attr)s"
msgstr "_create_copy: ソース仮想ディスク %(src)s の容量を仮想ディスク属性 %(attr)s から取得できません"

#: paxes_cinder/volume/drivers/svc/storwize_svc_driver_id.py:1681
#, python-format
msgid "leave: _create_copy: snapshot vdisk %(tgt_vdisk)s from vdisk %(src_vdisk)s"
msgstr "設定: _create_copy: 仮想ディスク %(src_vdisk)s からのスナップショット仮想ディスク %(tgt_vdisk)s"

#: paxes_cinder/volume/drivers/svc/storwize_svc_driver_id.py:1688
#, python-format
msgid "enter: _get_flashcopy_mapping_attributes: mapping %s"
msgstr "入力: _get_flashcopy_mapping_attributes: マッピング %s"

#: paxes_cinder/volume/drivers/svc/storwize_svc_driver_id.py:1711
#, python-format
msgid ""
"leave: _get_flashcopy_mapping_attributes: mapping %(fc_map_id)s, "
"attributes %(attributes)s"
msgstr ""
"設定: _get_flashcopy_mapping_attributes: マッピング %(fc_map_id)s、属性 "
"%(attributes)s"

#: paxes_cinder/volume/drivers/svc/storwize_svc_driver_id.py:1719
#, python-format
msgid "enter: _is_vdisk_defined: vdisk %s "
msgstr "入力: _is_vdisk_defined: 仮想ディスク %s "

#: paxes_cinder/volume/drivers/svc/storwize_svc_driver_id.py:1721
#, python-format
msgid "leave: _is_vdisk_defined: vdisk %(vdisk)s with %(str)s "
msgstr "設定: _is_vdisk_defined: %(str)s を指定した仮想ディスク %(vdisk)s "

#: paxes_cinder/volume/drivers/svc/storwize_svc_driver_id.py:1764
#: paxes_cinder/volume/drivers/svc/storwize_svc_product.py:1228
#, python-format
msgid "%(map_id)s [vdisk %(src)s to vdisk %(tgt)s]"
msgstr "%(map_id)s [仮想ディスク %(src)s から仮想ディスク %(tgt)s へ]"

#: paxes_cinder/volume/drivers/svc/storwize_svc_driver_id.py:1777
#, python-format
msgid ""
"To delete vdisk %(vdisk_id)s, increasing copyrate of flashcopy mapping "
"%(map)s from 0 to %(copyrate)s and waiting for completion."
msgstr ""
"NV-0B06E40 仮想ディスク %(vdisk_id)s を削除するため、FlashCopy マッピング %(map)s のコピー速度を 0 "
"から %(copyrate)s に上げて、完了するのを待機しています。"

#: paxes_cinder/volume/drivers/svc/storwize_svc_driver_id.py:1791
#: paxes_cinder/volume/drivers/svc/storwize_svc_product.py:1261
#, python-format
msgid "Vdisk %(id)s not involved in mapping %(src)s -> %(tgt)s"
msgstr "仮想ディスク %(id)s は %(src)s から %(tgt)s へのマッピングに含まれていません"

#: paxes_cinder/volume/drivers/svc/storwize_svc_driver_id.py:1798
#: paxes_cinder/volume/drivers/svc/storwize_svc_product.py:1268
#, python-format
msgid ""
"To allow deletion of vdisk %(vdisk_id)s, flashcopy mapping %(map)s with "
"status '%(status)s' was removed."
msgstr ""
"NV-4CA8ED6 仮想ディスク %(vdisk_id)s を削除できるようにするため、状況 '%(status)s' の FlashCopy "
"マッピング %(map)s が削除されました。"

#: paxes_cinder/volume/drivers/svc/storwize_svc_driver_id.py:1806
#: paxes_cinder/volume/drivers/svc/storwize_svc_product.py:1276
#, python-format
msgid ""
"To allow deletion of vdisk %(vdisk_id)s, waiting for flashcopy mapping "
"%(map)s with status '%(status)s' to complete."
msgstr ""
"NV-E66FA4E 仮想ディスク %(vdisk_id)s を削除できるようにするため、状況 '%(status)s' の FlashCopy "
"マッピング %(map)s が完了するのを待機しています。"

#: paxes_cinder/volume/drivers/svc/storwize_svc_driver_id.py:1816
#: paxes_cinder/volume/drivers/svc/storwize_svc_product.py:1286
#, python-format
msgid ""
"To allow deletion of vdisk %(vdisk_id)s, forcing removal of flashcopy "
"mapping %(map)s with status '%(status)s'"
msgstr ""
"NV-824284E 仮想ディスク %(vdisk_id)s を削除できるようにするため、状況 '%(status)s' の FlashCopy "
"マッピング %(map)s を強制的に削除しています"

#: paxes_cinder/volume/drivers/svc/storwize_svc_driver_id.py:1827
#: paxes_cinder/volume/drivers/svc/storwize_svc_product.py:1300
#, python-format
msgid ""
"To allow deletion of vdisk %(vdisk_id)s, prepared flashcopy mapping "
"%(map)s was removed."
msgstr ""
"NV-211FA49 仮想ディスク %(vdisk_id)s を削除できるようにするため、準備した FlashCopy マッピング %(map)s"
" が削除されました。"

#: paxes_cinder/volume/drivers/svc/storwize_svc_driver_id.py:1835
#: paxes_cinder/volume/drivers/svc/storwize_svc_product.py:1310
#, python-format
msgid ""
"To delete vdisk %(vdisk_id)s, flashcopy mapping %(map)s with status "
"'idle_or_copied' was removed."
msgstr ""
"NV-DA08F03 仮想ディスク %(vdisk_id)s を削除するため、状況 'idle_or_copied' の FlashCopy "
"マッピング %(map)s が削除されました。"

#: paxes_cinder/volume/drivers/svc/storwize_svc_driver_id.py:1841
#: paxes_cinder/volume/drivers/svc/storwize_svc_product.py:1318
#, python-format
msgid ""
"To delete vdisk %(vdisk_id)s, waiting for completion of flashcopy mapping"
" %(map)s, which is currently %(progress)s%% complete and has status "
"'%(status)s'."
msgstr ""
"NV-CE3069A 仮想ディスク %(vdisk_id)s を削除するため、FlashCopy マッピング %(map)s "
"が完了するのを待機しています。現在、このマッピングは %(progress)s%% 完了し、状況は '%(status)s' です。"

#: paxes_cinder/volume/drivers/svc/storwize_svc_driver_id.py:1881
msgid ""
"Flashcopy mapping copy rate is 0. Copy is not in progress. Return to "
"caller."
msgstr "NV-45B5480 FlashCopy マッピングのコピー速度は 0 です。コピーは進行中ではありません。呼び出し元に戻ります。"

#: paxes_cinder/volume/drivers/svc/storwize_svc_driver_id.py:1944
#, python-format
msgid "enter: _delete_vdisk: vdisk %s"
msgstr "入力: _delete_vdisk: 仮想ディスク %s"

#: paxes_cinder/volume/drivers/svc/storwize_svc_driver_id.py:1949
#, python-format
msgid "warning: Tried to delete vdisk %s but it does not exist."
msgstr "NV-E47B663 警告: 仮想ディスク %s を削除しようとしましたが、そのディスクは存在しません。"

#: paxes_cinder/volume/drivers/svc/storwize_svc_driver_id.py:1955
#, python-format
msgid "Removing vdisk %(vdisk_id)s"
msgstr "NV-E18AA05 仮想ディスク %(vdisk_id)s の削除中"

#: paxes_cinder/volume/drivers/svc/storwize_svc_driver_id.py:1968
#, python-format
msgid ""
"Hosts mapped to vdisk %(vdisk)s:\n"
"%(out)s"
msgstr ""
"NV-4159ED7 ホストが仮想ディスク %(vdisk)s に\n"
"マップされました:\n"
"%(out)s"

#: paxes_cinder/volume/drivers/svc/storwize_svc_driver_id.py:1974
#, python-format
msgid ""
"Existing FlashCopy mappings:\n"
"%(out)s"
msgstr ""
"NV-A345C87 FlashCopy マッピングの終了中:\n"
"%(out)s"

#: paxes_cinder/volume/drivers/svc/storwize_svc_driver_id.py:1982
#, python-format
msgid "leave: _delete_vdisk: vdisk %s"
msgstr "設定: _delete_vdisk: 仮想ディスク %s"

#: paxes_cinder/volume/drivers/svc/storwize_svc_driver_id.py:1992
#: paxes_cinder/volume/drivers/svc/storwize_svc_driver_id.py:2086
#: paxes_cinder/volume/drivers/svc/storwize_svc_driver_id.py:2135
#, python-format
msgid "adding volume_type_id to volume=%s"
msgstr "NV-86F0410 volume_type_id をボリューム=%s に追加中"

#: paxes_cinder/volume/drivers/svc/storwize_svc_driver_id.py:2014
#, python-format
msgid ""
"Starting deletion of volume %(volume_id)s.  There is no associated vdisk,"
" so no operation will be performed on the storage controller."
msgstr ""
"NV-04391FA ボリューム %(volume_id)s "
"の削除を開始中です。関連する仮想ディスクがないため、ストレージ・コントローラーで実行される操作はありません。"

#: paxes_cinder/volume/drivers/svc/storwize_svc_driver_id.py:2020
#, python-format
msgid "Starting deletion of volume %(volume_id)s, backed by vdisk %(vdisk_id)s"
msgstr "NV-0C0C004 仮想ディスク %(vdisk_id)s が支援するボリューム %(volume_id)s の削除を開始中です。"

#: paxes_cinder/volume/drivers/svc/storwize_svc_driver_id.py:2032
#, python-format
msgid ""
"delete_volume: vdisk mismatch: %(err)s. Performing no operation on the "
"storage controller"
msgstr ""
"NV-D258084 delete_volume: 仮想ディスクの不一致: "
"%(err)s。ストレージ・コントローラーではいずれの操作も実行されていません"

#: paxes_cinder/volume/drivers/svc/storwize_svc_driver_id.py:2038
#, python-format
msgid ""
"delete_volume: vdisk deleted: %(err)s. Performing no operation on the "
"storage controller"
msgstr ""
"NV-FC2A0B0 delete_volume: 仮想ディスクは削除されました: "
"%(err)s。ストレージ・コントローラーではいずれの操作も実行されていません"

#: paxes_cinder/volume/drivers/svc/storwize_svc_driver_id.py:2075
msgid "create_volume_from_snapshot: Source and destination size differ."
msgstr "NV-5A82296 create_volume_from_snapshot: ソースと宛先のサイズが異なります。"

#: paxes_cinder/volume/drivers/svc/storwize_svc_driver_id.py:2096
#, python-format
msgid "create_volume_from_snapshot:  Source vdisk %s does not exist"
msgstr "NV-4729BC4 create_volume_from_snapshot: ソース仮想ディスク %s は存在しません"

#: paxes_cinder/volume/drivers/svc/storwize_svc_driver_id.py:2123
msgid "create_cloned_volume: Source and destination size differ."
msgstr "NV-4DD8AF7 create_cloned_volume: ソースと宛先のサイズが異なります。"

#: paxes_cinder/volume/drivers/svc/storwize_svc_driver_id.py:2164
#: paxes_cinder/volume/drivers/svc/storwize_svc_product.py:1025
#, python-format
msgid "enter: extend_volume: volume %s"
msgstr "NV-826757D 入力: extend_volume: ボリューム %s"

#: paxes_cinder/volume/drivers/svc/storwize_svc_driver_id.py:2174
msgid "extend_volume: Extending a volume with snapshots is not supported."
msgstr "NV-E7C02C3 extend_volume: スナップショットを持つボリュームの拡張はサポートされていません。"

#: paxes_cinder/volume/drivers/svc/storwize_svc_driver_id.py:2186
#: paxes_cinder/volume/drivers/svc/storwize_svc_product.py:1051
#, python-format
msgid "leave: extend_volume: volume %s"
msgstr "NV-0CDE488 設定: extend_volume: ボリューム %s"

#: paxes_cinder/volume/drivers/svc/storwize_svc_driver_id.py:2202
#, python-format
msgid "enter: migrate_volume: id=%(id)s, host=%(host)s"
msgstr "入力: migrate_volume: id=%(id)s、host=%(host)s"

#: paxes_cinder/volume/drivers/svc/storwize_svc_driver_id.py:2234
msgid "migrate_volume started with more than one vdisk copy"
msgstr "複数の仮想ディスク・コピーを使用して migrate_volume が開始されました"

#: paxes_cinder/volume/drivers/svc/storwize_svc_driver_id.py:2252
#, python-format
msgid ""
"migrate_volume %(name)s - did not find success message in CLI output.\n"
" stdout: %(out)s\n"
" stderr: %(err)s"
msgstr ""
"migrate_volume %(name)s - CLI 出力に正常終了メッセージが見つかりませんでした。\n"
" stdout: %(out)s\n"
" stderr: %(err)s"

#: paxes_cinder/volume/drivers/svc/storwize_svc_driver_id.py:2264
msgid "migrate_volume: Could not get vdisk copy data"
msgstr "NV-E8B0820 migrate_volume: 仮想ディスク・コピー・データを取得できませんでした"

#: paxes_cinder/volume/drivers/svc/storwize_svc_driver_id.py:2279
#, python-format
msgid "leave: migrate_volume: id=%(id)s, host=%(host)s"
msgstr "設定: migrate_volume: id=%(id)s、host=%(host)s"

#: paxes_cinder/volume/drivers/svc/storwize_svc_driver_id.py:2301
msgid "Updating volume stats"
msgstr "ボリューム状態の更新中"

#: paxes_cinder/volume/drivers/svc/storwize_svc_driver_id.py:2324
msgid "Could not get pool data from the storage"
msgstr "NV-675559D ストレージからプール・データを取得できませんでした"

#: paxes_cinder/volume/drivers/svc/storwize_svc_driver_id.py:2325
msgid "_update_volume_stats: Could not get storage pool data"
msgstr "NV-F6BB258 _update_volume_stats: ストレージ・プール・データを取得できませんでした"

#: paxes_cinder/volume/drivers/svc/storwize_svc_driver_id.py:2412
msgid ""
"Illegal value specified for storwize_svc_vol_rsize: set to either a "
"percentage (0-100) or -1"
msgstr ""
"NV-8977C50 storwize_svc_vol_rsize に指定された値が正しくありません: パーセンテージ (0 から 100) "
"または -1 に設定してください"

#: paxes_cinder/volume/drivers/svc/storwize_svc_driver_id.py:2418
msgid ""
"Illegal value specified for storwize_svc_vol_warning: set to a percentage"
" (0-100)"
msgstr ""
"NV-80C1898 storwize_svc_vol_warning に指定された値が正しくありません: パーセンテージ (0 から 100) "
"を設定してください"

#: paxes_cinder/volume/drivers/svc/storwize_svc_driver_id.py:2425
msgid ""
"Illegal value specified for storwize_svc_vol_grainsize: set to either 32,"
" 64, 128, or 256"
msgstr ""
"NV-8A90F92 storwize_svc_vol_grainsize に指定された値が正しくありません: 32、64、128、または 256"
" に設定してください"

#: paxes_cinder/volume/drivers/svc/storwize_svc_driver_id.py:2432
msgid "System does not support compression"
msgstr "NV-90F35C9 システムでは圧縮がサポートされていません"

#: paxes_cinder/volume/drivers/svc/storwize_svc_driver_id.py:2437
msgid "If compression is set to True, rsize must also be set (not equal to -1)"
msgstr "NV-102C98D compression を True に設定した場合は、rsize も設定する必要があります (-1 以外)"

#: paxes_cinder/volume/drivers/svc/storwize_svc_driver_id.py:2443
#, python-format
msgid ""
"Illegal value %(prot)s specified for storwize_svc_connection_protocol: "
"valid values are %(enabled)s"
msgstr ""
"NV-5EBEB51 storwize_svc_connection_protocol に指定された値 %(prot)s が正しくありません: "
"有効な値は %(enabled)s です"

#: paxes_cinder/volume/drivers/svc/storwize_svc_driver_id.py:2451
#, python-format
msgid "I/O group %(iogrp)d is not valid; available I/O groups are %(avail)s"
msgstr "NV-9E31DDB 入出力グループ %(iogrp)d は無効です; 使用可能な入出力グループは %(avail)s です"

#: paxes_cinder/volume/drivers/svc/storwize_svc_driver_id.py:2465
#, python-format
msgid "enter: _execute_command_and_parse_attributes:  command %s"
msgstr "入力: _execute_command_and_parse_attributes: コマンド %s"

#: paxes_cinder/volume/drivers/svc/storwize_svc_driver_id.py:2477
#, python-format
msgid ""
"CLI Exception output:\n"
" command: %(cmd)s\n"
" stdout: %(out)s\n"
" stderr: %(err)s"
msgstr ""
"NV-A3B1CA4 CLI 例外出力:\n"
"コマンド: %(cmd)s\n"
" stdout: %(out)s\n"
" stderr: %(err)s"

#: paxes_cinder/volume/drivers/svc/storwize_svc_driver_id.py:2494
#, python-format
msgid ""
"leave: _execute_command_and_parse_attributes:\n"
"command: %(cmd)s\n"
"attributes: %(attr)s"
msgstr ""
"設定: _execute_command_and_parse_attributes:\n"
"コマンド: %(cmd)s\n"
"属性: %(attr)s"

#: paxes_cinder/volume/drivers/svc/storwize_svc_driver_id.py:2513
#, python-format
msgid ""
"_get_hdr_dic: attribute headers and values do not match.\n"
" Headers: %(header)s\n"
" Values: %(row)s"
msgstr ""
"_get_hdr_dic: 属性のヘッダーと値が適合していません。\n"
" ヘッダー: %(header)s\n"
" 値: %(row)s"

#: paxes_cinder/volume/drivers/svc/storwize_svc_driver_id.py:2521
#, python-format
msgid ""
"%(fun)s: Failed with unexpected CLI output.\n"
" Command: %(cmd)s\n"
"stdout: %(out)s\n"
"stderr: %(err)s\n"
msgstr ""
"NV-39015B6 %(fun)s: 予期しない CLI 出力により失敗しました。\n"
"コマンド: %(cmd)s\n"
" stdout: %(out)s\n"
" stderr: %(err)s\n"

#: paxes_cinder/volume/drivers/svc/storwize_svc_driver_id.py:2535
#, python-format
msgid ""
"%(fun)s: Failed with unexpected CLI output.\n"
" Command: %(cmd)s\n"
" stdout: %(out)s\n"
" stderr: %(err)s"
msgstr ""
"%(fun)s: 予期しない CLI 出力により失敗しました。\n"
"コマンド: %(cmd)s\n"
" stdout: %(out)s\n"
" stderr: %(err)s"

#: paxes_cinder/volume/drivers/svc/storwize_svc_driver_id.py:2543
#, python-format
msgid "Did not find expected column in %(fun)s: %(hdr)s"
msgstr "NV-BEC3CF8 予期された列が %(fun)s で見つかりませんでした: %(hdr)s"

#: paxes_cinder/volume/drivers/svc/storwize_svc_product.py:103
#, python-format
msgid ""
"StorwizeSVCProductDriver: start flashcopy mapping polling timer, polling "
"interval: %(intval)s seconds"
msgstr ""
"NV-796256C StorwizeSVCProductDriver: FlashCopy "
"マッピングのポーリング・タイマーを開始します。ポーリング間隔: %(intval)s 秒"

#: paxes_cinder/volume/drivers/svc/storwize_svc_product.py:328
#, python-format
msgid ""
"The volume %(name)s is in the error state and not a candidate for "
"management.  vdisk status: %(status)s  vdisk id: %(vdisk_id)s  vdisk uid:"
" %(vdisk_uid)s  "
msgstr ""
"ボリューム %(name)s はエラー状態にあるため、管理対象の候補ではありません。仮想ディスク状況: %(status)s、仮想ディスク ID:"
" %(vdisk_id)s、仮想ディスク UID: %(vdisk_uid)s"

#: paxes_cinder/volume/drivers/svc/storwize_svc_product.py:592
#, python-format
msgid ""
"The connector %(connector)s does not contain the required keys, which are"
" %(expected_fc_keys)s.or %(expected_iscsi_keys)s"
msgstr ""
"コネクター %(connector)s に必要なキーが含まれていません。キーは、%(expected_fc_keys)s または "
"%(expected_iscsi_keys)s です"

#: paxes_cinder/volume/drivers/svc/storwize_svc_product.py:647
#, python-format
msgid "Incorporating WWPNS for Node %(node_id)s: %(wwpns)s"
msgstr "NV-365ED6F ノード %(node_id)s の WWPN を取り込み中: %(wwpns)s"

#: paxes_cinder/volume/drivers/svc/storwize_svc_product.py:659
#, python-format
msgid ""
"Attachment for host '%(host)s' to %(storage)s for volume %(volume)s "
"expects zoning between initiator WWPNs %(initiators)s and target WWPNs "
"%(targets)s"
msgstr ""
"NV-0F22247 ボリューム %(volume)s の %(storage)s に対するホスト '%(host)s' "
"の接続では、イニシエーター WWPN %(initiators)s と宛先 WWPN %(targets)s の間のゾーニングが必要です"

#: paxes_cinder/volume/drivers/svc/storwize_svc_product.py:721
#, python-format
msgid "Mapping initiator %(phy)s to node %(node)s"
msgstr "NV-5DC7B55 イニシエーター %(phy)s をノード %(node)s にマッピング中"

#: paxes_cinder/volume/drivers/svc/storwize_svc_product.py:766
#, python-format
msgid ""
"Fabric %(fabric)s does not have visibility to any WWPNs in node %(node)s,"
" part of iogrp %(iogrp)s of storage controller %(name)s. WWPNs visible on"
" the fabric are %(visible)s. WWPNs on the controller are %(available)s."
msgstr ""
"ファブリック %(fabric)s からは、ストレージ・コントローラー %(name)s の iogrp %(iogrp)s の一部である、ノード"
" %(node)s 内の WWPN を認識できません。ファブリック上で認識可能な WWPN は %(visible)s です。コントローラー上の "
"WWPN は %(available)s です。"

#: paxes_cinder/volume/drivers/svc/storwize_svc_product.py:811
msgid "Zoning for single fabric, one initiator."
msgstr "NV-6E5D37F 単一ファブリック、1 つのイニシエーター用にゾーニング中です。"

#: paxes_cinder/volume/drivers/svc/storwize_svc_product.py:821
msgid "Zoning for single fabric, two initiators."
msgstr "NV-2E0EF21 単一ファブリック、2 つのイニシエーター用にゾーニング中です。"

#: paxes_cinder/volume/drivers/svc/storwize_svc_product.py:835
#, python-format
msgid ""
"Zoning for single fabric, general case due to %(count)s initiators on "
"fabric."
msgstr "NV-D9A5CD2 %(count)s 個のイニシエーターがファブリックにあるため、単一ファブリック、一般事例用にゾーニング中です。"

#: paxes_cinder/volume/drivers/svc/storwize_svc_product.py:845
msgid "Zoning for dual fabric, one initiator per fabric."
msgstr "NV-EE35C79 二重ファブリック、ファブリックごとに 1 つのイニシエーター用にゾーニング中です。"

#: paxes_cinder/volume/drivers/svc/storwize_svc_product.py:864
msgid "Zoning for dual fabric, two initiators per fabric."
msgstr "NV-C638EFA 二重ファブリック、ファブリックごとに 2 つのイニシエーター用にゾーニング中です。"

#: paxes_cinder/volume/drivers/svc/storwize_svc_product.py:884
#, python-format
msgid ""
"Zoning for dual fabric, general case due to %(count1)s initiators on "
"first fabric and %(count2)s initiators on second fabric."
msgstr ""
"NV-4351BA7 %(count1)s 個のイニシエーターが 1 番目のファブリックにあり、%(count2)s 個のイニシエーターが 2 "
"番目のファブリックにあるため、二重ファブリック、一般事例用にゾーニング中です。"

#: paxes_cinder/volume/drivers/svc/storwize_svc_product.py:894
#, python-format
msgid "Zoning for general case due to %(count)s fabrics."
msgstr "NV-0733A1E %(count)s 個のファブリックがあるため、一般事例用にゾーニング中です。"

#: paxes_cinder/volume/drivers/svc/storwize_svc_product.py:911
#, python-format
msgid "Creating zones: %r"
msgstr "NV-70BDC4D ゾーンの作成中: %r"

#: paxes_cinder/volume/drivers/svc/storwize_svc_product.py:923
#, python-format
msgid "Requested mapping for initiators  %(initiators)s and targets %(targets)s"
msgstr "NV-35F3CC8 イニシエーター %(initiators)s と宛先 %(targets)s のマッピングが要求されました"

#: paxes_cinder/volume/drivers/svc/storwize_svc_product.py:941
#: paxes_cinder/volume/drivers/svc/storwize_svc_product.py:950
#, python-format
msgid "Returned mapping is %(mapping)s"
msgstr "NV-10E28B0 返されたマッピングは %(mapping)s です"

#: paxes_cinder/volume/drivers/svc/storwize_svc_product.py:976
#, python-format
msgid "Terminating connection with parameters %(connector)sconnector"
msgstr "NV-4EFE246 パラメーター %(connector)s コネクターとの接続を終了中"

#: paxes_cinder/volume/drivers/svc/storwize_svc_product.py:986
#, python-format
msgid "Removing zones for initiators: %(initiator_list)s"
msgstr "NV-CC588B5 イニシエーターのゾーンを削除中: %(initiator_list)s"

#: paxes_cinder/volume/drivers/svc/storwize_svc_product.py:996
#, python-format
msgid ""
"There was a failure when the zone manager attempted to remove zones "
"created for WWPNs %(wwpns)s during detach of volume %(vol)s."
msgstr ""
"NV-AA064A4 ボリューム %(vol)s を切り離している間、ゾーン・マネージャーが WWPN %(wwpns)s "
"用に作成されたゾーンを削除しようと試みているときに、障害がありました。"

#: paxes_cinder/volume/drivers/svc/storwize_svc_product.py:1083
#, python-format
msgid "SSH Pool: %d free, %d waiting, in-flight commands:"
msgstr "NV-F9DD698 SSH プール: %d 空き、%d 待機中、処理中のコマンド:"

#: paxes_cinder/volume/drivers/svc/storwize_svc_product.py:1087
#, python-format
msgid " %(duration).2f %(commands)s"
msgstr "NV-98D8DC3  %(duration).2f %(commands)s"

#: paxes_cinder/volume/drivers/svc/storwize_svc_product.py:1141
#, python-format
msgid ""
"vdisk %(vdsk)s has been added to the flashcopy mapping delete queue with "
"priority %(pri)s."
msgstr "NV-38E83B6 仮想ディスク %(vdsk)s は、FlashCopy マッピング削除キューに優先順位 %(pri)s として追加されました。"

#: paxes_cinder/volume/drivers/svc/storwize_svc_product.py:1149
#, python-format
msgid ""
"Successfully returned from flashcopy mapping waiter for vdisk %(vdsk)s, "
"returned value: %(ret)s, total wait time: %(wt)s seconds."
msgstr ""
"NV-62F28E6 仮想ディスク %(vdsk)s の FlashCopy マッピング・ウェイターから正常に戻りました。戻り値: "
"%(ret)s、合計待ち時間: %(wt)s 秒。"

#: paxes_cinder/volume/drivers/svc/storwize_svc_product.py:1166
#, python-format
msgid ""
"Exception happened when waiting for flashcopy mapping handling for vdisk "
"%(vdsk)s, total wait time: %(wt)s seconds."
msgstr ""
"NV-71EC636 仮想ディスク %(vdsk)s の FlashCopy マッピング処理を待機中に、例外が発生しました。合計待ち時間: "
"%(wt)s 秒。"

#: paxes_cinder/volume/drivers/svc/storwize_svc_product.py:1172
#, python-format
msgid ""
"Removed flashcopy mappings waiter from waiting queue for vdisk %(vdsk)s "
"deletion."
msgstr "NV-46703B0 仮想ディスク %(vdsk)s 削除のための待機キューから、FlashCopy マッピング・ウェイターが削除されました。"

#: paxes_cinder/volume/drivers/svc/storwize_svc_product.py:1183
#, python-format
msgid "Flashcopy mapping delete queue: %(vdsks)s"
msgstr "NV-CA4A211 FlashCopy マッピング削除キュー: %(vdsks)s"

#: paxes_cinder/volume/drivers/svc/storwize_svc_product.py:1193
#, python-format
msgid ""
"Flashcopy mapping delete queue: %(cnt)s vdisks pending delete, average "
"wait time: %(avg)s seconds"
msgstr ""
"NV-91BB641 FlashCopy マッピング削除キュー: %(cnt)s 個の仮想ディスクが削除の保留中です。平均待ち時間: "
"%(avg)s 秒"

#: paxes_cinder/volume/drivers/svc/storwize_svc_product.py:1242
#, python-format
msgid "fcmapping_handler: %(err)s"
msgstr "fcmapping_handler: %(err)s"

#: paxes_cinder/volume/drivers/svc/storwize_svc_product.py:1245
#, python-format
msgid ""
"fcmapping_handler: to delete vdisk %(vdisk_id)s, increasing copyrate of "
"flashcopy mapping %(map)s from 0 to %(copyrate)s and waiting for "
"completion."
msgstr ""
"NV-EE5BEB1 fcmapping_handler: 仮想ディスク %(vdisk_id)s を削除するため、FlashCopy マッピング"
" %(map)s のコピー速度を 0 から %(copyrate)s に上げて、完了するのを待機しています。"

#: paxes_cinder/volume/drivers/svc/storwize_svc_product.py:1357
#, python-format
msgid ""
"Exception happened during processing flashcopy mapping per vdisk %(vdsk)s"
" deletion: %(err)s"
msgstr "NV-71C30D1 仮想ディスク %(vdsk)s 削除に従って FlashCopy マッピングを処理中に、例外が発生しました: %(err)s"

#: paxes_cinder/volume/drivers/svc/storwize_svc_product.py:1387
#, python-format
msgid ""
"Duration of fcmapping_handler timer: %(runtime)s seconds, %(pct)s%% of "
"fixed polling interval."
msgstr ""
"NV-80870AC fcmapping_handler タイマーの所要時間: %(runtime)s 秒、%(pct)s%% "
"の固定ポーリング間隔。"

#: paxes_cinder/zonemanager/paxes_fc_zone_manager.py:93
#, python-format
msgid "Fabric names are not unique: %(fabric_names)s"
msgstr "NV-2ED2D0B ファブリック名が固有ではありません: %(fabric_names)s"

#: paxes_cinder/zonemanager/paxes_fc_zone_manager.py:261
#, python-format
msgid "Connection established to fabric %(f_name)s"
msgstr "NV-41B567C ファブリック %(f_name)s との接続が確立されました"

#: paxes_cinder/zonemanager/paxes_fc_zone_manager.py:376
#, python-format
msgid "Zones to be created for %(fabric)s are %(zones)r"
msgstr "NV-2E6EE4A %(fabric)s 用に作成されるゾーンは %(zones)r です"

#: paxes_cinder/zonemanager/paxes_fc_zone_manager.py:410
#, python-format
msgid "%(fabric_descriptor)s: deleting zones %(zone_list)s"
msgstr "NV-C3FDFEA %(fabric_descriptor)s: ゾーンの削除中: %(zone_list)s"

#: paxes_cinder/zonemanager/paxes_fc_zone_manager.py:449
#, python-format
msgid "Returned data from get_nameserver_info() is %(info)r"
msgstr "NV-7863F08 get_nameserver_info() から返されたデータは %(info)r です"

#: paxes_cinder/zonemanager/drivers/brocade/brcd_fc_zone_client_cli.py:122
msgid "Could not connect"
msgstr "NV-07C9AAF 接続できませんでした"

#: paxes_cinder/zonemanager/drivers/brocade/brcd_fc_zone_client_cli.py:124
#, python-format
msgid "SSH Client created for %s"
msgstr "NV-08C2923 %s 用の SSH クライアントが作成されました"

#: paxes_cinder/zonemanager/drivers/brocade/brcd_fc_zone_client_cli.py:187
#, python-format
msgid "Failed getting active zone set from %s"
msgstr "NV-373682A アクティブ・ゾーン・セットを %s から取得できませんでした"

#: paxes_cinder/zonemanager/drivers/brocade/brcd_fc_zone_client_cli.py:218
msgid "Malformed zone configuration"
msgstr "NV-9BF2FBF 誤った形式のゾーン構成"

#: paxes_cinder/zonemanager/drivers/brocade/brcd_fc_zone_client_cli.py:220
#, python-format
msgid "Failed getting active zone set from fabric %s"
msgstr "NV-A5B77A2 アクティブ・ゾーン・セットをファブリック %s から取得できませんでした"

#: paxes_cinder/zonemanager/drivers/brocade/brcd_fc_zone_client_cli.py:259
#, python-format
msgid "Add Zones - Zones passed: %s"
msgstr "NV-8A18A84 ゾーンの追加 - 渡されたゾーン: %s"

#: paxes_cinder/zonemanager/drivers/brocade/brcd_fc_zone_client_cli.py:267
#, python-format
msgid "Adding zone failed. Error in getting active zone set from fabric %s"
msgstr "NV-C692314 ゾーンの追加が失敗しました。アクティブ・ゾーン・セットをファブリック %s から取得中にエラーが発生しました"

#: paxes_cinder/zonemanager/drivers/brocade/brcd_fc_zone_client_cli.py:276
#, python-format
msgid "Zone %(zoneName)s already contains required members"
msgstr "NV-EADDEDC ゾーン %(zoneName)s には、必要なメンバーが既に含まれています"

#: paxes_cinder/zonemanager/drivers/brocade/brcd_fc_zone_client_cli.py:282
#, python-format
msgid "Deleted Zone before insert : %s"
msgstr "NV-4C9797D 挿入前にゾーンが削除されました: %s"

#: paxes_cinder/zonemanager/drivers/brocade/brcd_fc_zone_client_cli.py:286
#, python-format
msgid "Deleting zone failed %s"
msgstr "NV-C1A773E ゾーンの削除に失敗しました: %s"

#: paxes_cinder/zonemanager/drivers/brocade/brcd_fc_zone_client_cli.py:294
#, python-format
msgid "Adding zone, cmd to run %s"
msgstr "NV-D2B3DDC ゾーンの追加中、実行するコマンド: %s"

#: paxes_cinder/zonemanager/drivers/brocade/brcd_fc_zone_client_cli.py:301
#: paxes_cinder/zonemanager/drivers/brocade/brcd_fc_zone_client_cli.py:304
#: paxes_cinder/zonemanager/drivers/brocade/brcd_fc_zone_client_cli.py:338
#: paxes_cinder/zonemanager/drivers/brocade/brcd_fc_zone_client_cli.py:341
#, python-format
msgid "Adding zone failed, cmd %s"
msgstr "NV-3F8FCCF ゾーンの追加が失敗しました。コマンド %s"

#: paxes_cinder/zonemanager/drivers/brocade/brcd_fc_zone_client_cli.py:312
msgid "No new zones created"
msgstr "NV-145C307 新規ゾーンは作成されませんでした"

#: paxes_cinder/zonemanager/drivers/brocade/brcd_fc_zone_client_cli.py:322
#, python-format
msgid "Zoneset create operation failed with output %s"
msgstr "NV-0645570 ゾーン・セットの作成操作が失敗しました。出力: %s"

#: paxes_cinder/zonemanager/drivers/brocade/brcd_fc_zone_client_cli.py:330
#, python-format
msgid "cfgAdd operation failed : %s"
msgstr "NV-C8F3EB6 cfgAdd 操作が失敗しました: %s"

#: paxes_cinder/zonemanager/drivers/brocade/brcd_fc_zone_client_cli.py:343
msgid "Zoning completed"
msgstr "NV-BC5301E ゾーニングが完了しました"

#: paxes_cinder/zonemanager/drivers/brocade/brcd_fc_zone_client_cli.py:373
#, python-format
msgid "Failed getting active zones from fabric %s"
msgstr "NV-21CE132 アクティブ・ゾーンをファブリック %s から取得できませんでした"

#: paxes_cinder/zonemanager/drivers/brocade/brcd_fc_zone_client_cli.py:395
#: paxes_cinder/zonemanager/drivers/brocade/brcd_fc_zone_client_cli.py:398
#, python-format
msgid "Deleting zones failed, cmd %s"
msgstr "NV-AFACFBC ゾーンの削除が失敗しました。コマンド %s"

#: paxes_cinder/zonemanager/drivers/brocade/brcd_fc_zone_client_cli.py:414
#, python-format
msgid "Failed collecting nsshow info for fabric %s"
msgstr "NV-6039569 ファブリック %s の nsshow 情報の収集に失敗しました"

#: paxes_cinder/zonemanager/drivers/brocade/brcd_fc_zone_client_cli.py:421
#, python-format
msgid "Failed collecting nscamshow info for fabric %s"
msgstr "NV-A1992B9 ファブリック %s の nscamshow 情報の収集に失敗しました"

#: paxes_cinder/zonemanager/drivers/brocade/brcd_fc_zone_client_cli.py:453
#, python-format
msgid "Problem: %(problem)s"
msgstr "NV-D20CB78 問題: %(problem)s"

#: paxes_cinder/zonemanager/drivers/brocade/brcd_fc_zone_client_cli.py:471
#, python-format
msgid "Will retry after %(seconds)s seconds..."
msgstr "NV-A7C85C7 %(seconds)s 秒後に再試行します..."

#: paxes_cinder/zonemanager/drivers/brocade/brcd_fc_zone_client_cli.py:490
#, python-format
msgid "Failed closing SSH connection %s"
msgstr "NV-3EA57B2 SSH 接続 %s を閉じることができませんでした"

#: paxes_cinder/zonemanager/drivers/brocade/brcd_fc_zone_client_cli.py:512
#: paxes_cinder/zonemanager/drivers/brocade/brcd_fc_zone_client_cli.py:561
#, python-format
msgid "running: '%s'"
msgstr "NV-081F69F 実行中: '%s'"

#: paxes_cinder/zonemanager/drivers/brocade/brcd_fc_zone_client_cli.py:521
#, python-format
msgid "Returned data was %r"
msgstr "NV-93F16B7 返されたデータは %r でした"

#: paxes_cinder/zonemanager/drivers/brocade/brcd_fc_zone_client_cli.py:535
#, python-format
msgid "Error running command via ssh: %s"
msgstr "NV-20D0255 ssh を介してコマンドを実行中にエラーが発生しました: %s"

#: paxes_cinder/zonemanager/drivers/brocade/brcd_fc_zone_client_cli.py:587
#, python-format
msgid "Error while checking zoning txn status: %s"
msgstr "NV-2D4C6DF ゾーニング・トランザクション状況の検査中にエラーが発生しました: %s"

#: paxes_cinder/zonemanager/drivers/brocade/brcd_fc_zone_client_cli.py:599
#, python-format
msgid "Executing: %s"
msgstr "NV-4EBB354 実行中: %s"

#: paxes_cinder/zonemanager/drivers/brocade/brcd_fc_zone_client_cli.py:609
#, python-format
msgid "CLI execution returned: %s"
msgstr "NV-538FB7E CLI の実行により、以下が返されました: %s"

#: paxes_cinder/zonemanager/drivers/brocade/brcd_fc_zone_client_cli.py:633
#, python-format
msgid "Error executing command %(cmd)s: %s"
msgstr "コマンド %(cmd)s の実行中にエラーが発生しました: %s"

#: paxes_cinder/zonemanager/drivers/brocade/brcd_fc_zone_client_cli.py:648
#, python-format
msgid "Failed when executing command '%(cmd)s': %(err)s"
msgstr "NV-B5BA5A5 コマンド '%(cmd)s' を実行しているときに失敗しました: %(err)s"

#: paxes_cinder/zonemanager/drivers/brocade/brcd_fc_zone_client_cli.py:670
#, python-format
msgid "Malformed nameserver output is: %s"
msgstr "NV-07E23F0 誤った形式のネームサーバー出力: %s"

#: paxes_cinder/zonemanager/drivers/brocade/brcd_fc_zone_client_cli.py:672
msgid "Malformed nameserver info"
msgstr "NV-4331BBF 誤った形式のネームサーバー情報"

